[2022-04-27 17:47:33 +0800] [40517] [INFO] Running on https://0.0.0.0:6843 (CTRL + C to quit)
[2022-04-27 17:47:33 +0800] [40517] [INFO] Running on http://0.0.0.0:6880 (CTRL + C to quit)
[2022-04-27 18:26:08 +0800] [41858] [INFO] Running on https://0.0.0.0:6843 (CTRL + C to quit)
[2022-04-27 18:26:08 +0800] [41858] [INFO] Running on http://0.0.0.0:6880 (CTRL + C to quit)
[2022-04-27 18:26:50 +0800] [41858] [ERROR] Error in ASGI Framework
Traceback (most recent call last):
  File "/Users/zhangjun/PycharmProjects/OSSGPAPI/venv/lib/python3.8/site-packages/hypercorn/trio/task_group.py", line 21, in _handle
    await invoke_asgi(app, scope, receive, send)
  File "/Users/zhangjun/PycharmProjects/OSSGPAPI/venv/lib/python3.8/site-packages/hypercorn/utils.py", line 247, in invoke_asgi
    await app(scope, receive, send)
  File "/Users/zhangjun/PycharmProjects/OSSGPAPI/venv/lib/python3.8/site-packages/fastapi/applications.py", line 261, in __call__
    await super().__call__(scope, receive, send)
  File "/Users/zhangjun/PycharmProjects/OSSGPAPI/venv/lib/python3.8/site-packages/starlette/applications.py", line 112, in __call__
    await self.middleware_stack(scope, receive, send)
  File "/Users/zhangjun/PycharmProjects/OSSGPAPI/venv/lib/python3.8/site-packages/starlette/middleware/errors.py", line 181, in __call__
    raise exc
  File "/Users/zhangjun/PycharmProjects/OSSGPAPI/venv/lib/python3.8/site-packages/starlette/middleware/errors.py", line 159, in __call__
    await self.app(scope, receive, _send)
  File "/Users/zhangjun/PycharmProjects/OSSGPAPI/venv/lib/python3.8/site-packages/starlette/middleware/cors.py", line 92, in __call__
    await self.simple_response(scope, receive, send, request_headers=headers)
  File "/Users/zhangjun/PycharmProjects/OSSGPAPI/venv/lib/python3.8/site-packages/starlette/middleware/cors.py", line 147, in simple_response
    await self.app(scope, receive, send)
  File "/Users/zhangjun/PycharmProjects/OSSGPAPI/venv/lib/python3.8/site-packages/starlette/exceptions.py", line 82, in __call__
    raise exc
  File "/Users/zhangjun/PycharmProjects/OSSGPAPI/venv/lib/python3.8/site-packages/starlette/exceptions.py", line 71, in __call__
    await self.app(scope, receive, sender)
  File "/Users/zhangjun/PycharmProjects/OSSGPAPI/venv/lib/python3.8/site-packages/fastapi/middleware/asyncexitstack.py", line 21, in __call__
    raise e
  File "/Users/zhangjun/PycharmProjects/OSSGPAPI/venv/lib/python3.8/site-packages/fastapi/middleware/asyncexitstack.py", line 18, in __call__
    await self.app(scope, receive, send)
  File "/Users/zhangjun/PycharmProjects/OSSGPAPI/venv/lib/python3.8/site-packages/starlette/routing.py", line 656, in __call__
    await route.handle(scope, receive, send)
  File "/Users/zhangjun/PycharmProjects/OSSGPAPI/venv/lib/python3.8/site-packages/starlette/routing.py", line 259, in handle
    await self.app(scope, receive, send)
  File "/Users/zhangjun/PycharmProjects/OSSGPAPI/venv/lib/python3.8/site-packages/starlette/routing.py", line 61, in app
    response = await func(request)
  File "/Users/zhangjun/PycharmProjects/OSSGPAPI/venv/lib/python3.8/site-packages/fastapi/routing.py", line 227, in app
    raw_response = await run_endpoint_function(
  File "/Users/zhangjun/PycharmProjects/OSSGPAPI/venv/lib/python3.8/site-packages/fastapi/routing.py", line 160, in run_endpoint_function
    return await dependant.call(**values)
  File "/Users/zhangjun/PycharmProjects/OSSGPAPI/main.py", line 149, in login
    user = security.authenticate_user(apiusers, form_data.username, form_data.password)
  File "/Users/zhangjun/PycharmProjects/OSSGPAPI/core/security.py", line 68, in authenticate_user
    user = get_user(fake_db, username)
  File "/Users/zhangjun/PycharmProjects/OSSGPAPI/core/security.py", line 63, in get_user
    return UserInDB(**guser)
  File "pydantic/main.py", line 331, in pydantic.main.BaseModel.__init__
pydantic.error_wrappers.ValidationError: 1 validation error for UserInDB
hashed_password
  field required (type=value_error.missing)
[2022-04-27 18:31:17 +0800] [41858] [INFO] Running on https://0.0.0.0:6843 (CTRL + C to quit)
[2022-04-27 18:31:17 +0800] [41858] [INFO] Running on http://0.0.0.0:6880 (CTRL + C to quit)
[2022-04-27 18:31:22 +0800] [42015] [INFO] Running on https://0.0.0.0:6843 (CTRL + C to quit)
[2022-04-27 18:31:22 +0800] [42015] [INFO] Running on http://0.0.0.0:6880 (CTRL + C to quit)
[2022-04-27 18:31:26 +0800] [42015] [ERROR] Error in ASGI Framework
Traceback (most recent call last):
  File "/Users/zhangjun/PycharmProjects/OSSGPAPI/venv/lib/python3.8/site-packages/hypercorn/trio/task_group.py", line 21, in _handle
    await invoke_asgi(app, scope, receive, send)
  File "/Users/zhangjun/PycharmProjects/OSSGPAPI/venv/lib/python3.8/site-packages/hypercorn/utils.py", line 247, in invoke_asgi
    await app(scope, receive, send)
  File "/Users/zhangjun/PycharmProjects/OSSGPAPI/venv/lib/python3.8/site-packages/fastapi/applications.py", line 261, in __call__
    await super().__call__(scope, receive, send)
  File "/Users/zhangjun/PycharmProjects/OSSGPAPI/venv/lib/python3.8/site-packages/starlette/applications.py", line 112, in __call__
    await self.middleware_stack(scope, receive, send)
  File "/Users/zhangjun/PycharmProjects/OSSGPAPI/venv/lib/python3.8/site-packages/starlette/middleware/errors.py", line 181, in __call__
    raise exc
  File "/Users/zhangjun/PycharmProjects/OSSGPAPI/venv/lib/python3.8/site-packages/starlette/middleware/errors.py", line 159, in __call__
    await self.app(scope, receive, _send)
  File "/Users/zhangjun/PycharmProjects/OSSGPAPI/venv/lib/python3.8/site-packages/starlette/middleware/cors.py", line 92, in __call__
    await self.simple_response(scope, receive, send, request_headers=headers)
  File "/Users/zhangjun/PycharmProjects/OSSGPAPI/venv/lib/python3.8/site-packages/starlette/middleware/cors.py", line 147, in simple_response
    await self.app(scope, receive, send)
  File "/Users/zhangjun/PycharmProjects/OSSGPAPI/venv/lib/python3.8/site-packages/starlette/exceptions.py", line 82, in __call__
    raise exc
  File "/Users/zhangjun/PycharmProjects/OSSGPAPI/venv/lib/python3.8/site-packages/starlette/exceptions.py", line 71, in __call__
    await self.app(scope, receive, sender)
  File "/Users/zhangjun/PycharmProjects/OSSGPAPI/venv/lib/python3.8/site-packages/fastapi/middleware/asyncexitstack.py", line 21, in __call__
    raise e
  File "/Users/zhangjun/PycharmProjects/OSSGPAPI/venv/lib/python3.8/site-packages/fastapi/middleware/asyncexitstack.py", line 18, in __call__
    await self.app(scope, receive, send)
  File "/Users/zhangjun/PycharmProjects/OSSGPAPI/venv/lib/python3.8/site-packages/starlette/routing.py", line 656, in __call__
    await route.handle(scope, receive, send)
  File "/Users/zhangjun/PycharmProjects/OSSGPAPI/venv/lib/python3.8/site-packages/starlette/routing.py", line 259, in handle
    await self.app(scope, receive, send)
  File "/Users/zhangjun/PycharmProjects/OSSGPAPI/venv/lib/python3.8/site-packages/starlette/routing.py", line 61, in app
    response = await func(request)
  File "/Users/zhangjun/PycharmProjects/OSSGPAPI/venv/lib/python3.8/site-packages/fastapi/routing.py", line 227, in app
    raw_response = await run_endpoint_function(
  File "/Users/zhangjun/PycharmProjects/OSSGPAPI/venv/lib/python3.8/site-packages/fastapi/routing.py", line 160, in run_endpoint_function
    return await dependant.call(**values)
  File "/Users/zhangjun/PycharmProjects/OSSGPAPI/main.py", line 149, in login
    user = security.authenticate_user(apiusers, form_data.username, form_data.password)
  File "/Users/zhangjun/PycharmProjects/OSSGPAPI/core/security.py", line 68, in authenticate_user
    user = get_user(fake_db, username)
  File "/Users/zhangjun/PycharmProjects/OSSGPAPI/core/security.py", line 63, in get_user
    return UserInDB(**guser)
  File "pydantic/main.py", line 331, in pydantic.main.BaseModel.__init__
pydantic.error_wrappers.ValidationError: 1 validation error for UserInDB
hashed_password
  field required (type=value_error.missing)
[2022-04-27 18:31:54 +0800] [42015] [INFO] Running on https://0.0.0.0:6843 (CTRL + C to quit)
[2022-04-27 18:31:54 +0800] [42015] [INFO] Running on http://0.0.0.0:6880 (CTRL + C to quit)
[2022-04-27 18:31:54 +0800] [42015] [ERROR] Error in ASGI Framework
Traceback (most recent call last):
  File "/Users/zhangjun/PycharmProjects/OSSGPAPI/venv/lib/python3.8/site-packages/hypercorn/trio/task_group.py", line 21, in _handle
    await invoke_asgi(app, scope, receive, send)
  File "/Users/zhangjun/PycharmProjects/OSSGPAPI/venv/lib/python3.8/site-packages/hypercorn/utils.py", line 247, in invoke_asgi
    await app(scope, receive, send)
  File "/Users/zhangjun/PycharmProjects/OSSGPAPI/venv/lib/python3.8/site-packages/fastapi/applications.py", line 261, in __call__
    await super().__call__(scope, receive, send)
  File "/Users/zhangjun/PycharmProjects/OSSGPAPI/venv/lib/python3.8/site-packages/starlette/applications.py", line 112, in __call__
    await self.middleware_stack(scope, receive, send)
  File "/Users/zhangjun/PycharmProjects/OSSGPAPI/venv/lib/python3.8/site-packages/starlette/middleware/errors.py", line 181, in __call__
    raise exc
  File "/Users/zhangjun/PycharmProjects/OSSGPAPI/venv/lib/python3.8/site-packages/starlette/middleware/errors.py", line 159, in __call__
    await self.app(scope, receive, _send)
  File "/Users/zhangjun/PycharmProjects/OSSGPAPI/venv/lib/python3.8/site-packages/starlette/middleware/cors.py", line 92, in __call__
    await self.simple_response(scope, receive, send, request_headers=headers)
  File "/Users/zhangjun/PycharmProjects/OSSGPAPI/venv/lib/python3.8/site-packages/starlette/middleware/cors.py", line 147, in simple_response
    await self.app(scope, receive, send)
  File "/Users/zhangjun/PycharmProjects/OSSGPAPI/venv/lib/python3.8/site-packages/starlette/exceptions.py", line 82, in __call__
    raise exc
  File "/Users/zhangjun/PycharmProjects/OSSGPAPI/venv/lib/python3.8/site-packages/starlette/exceptions.py", line 71, in __call__
    await self.app(scope, receive, sender)
  File "/Users/zhangjun/PycharmProjects/OSSGPAPI/venv/lib/python3.8/site-packages/fastapi/middleware/asyncexitstack.py", line 21, in __call__
    raise e
  File "/Users/zhangjun/PycharmProjects/OSSGPAPI/venv/lib/python3.8/site-packages/fastapi/middleware/asyncexitstack.py", line 18, in __call__
    await self.app(scope, receive, send)
  File "/Users/zhangjun/PycharmProjects/OSSGPAPI/venv/lib/python3.8/site-packages/starlette/routing.py", line 656, in __call__
    await route.handle(scope, receive, send)
  File "/Users/zhangjun/PycharmProjects/OSSGPAPI/venv/lib/python3.8/site-packages/starlette/routing.py", line 259, in handle
    await self.app(scope, receive, send)
  File "/Users/zhangjun/PycharmProjects/OSSGPAPI/venv/lib/python3.8/site-packages/starlette/routing.py", line 61, in app
    response = await func(request)
  File "/Users/zhangjun/PycharmProjects/OSSGPAPI/venv/lib/python3.8/site-packages/fastapi/routing.py", line 227, in app
    raw_response = await run_endpoint_function(
  File "/Users/zhangjun/PycharmProjects/OSSGPAPI/venv/lib/python3.8/site-packages/fastapi/routing.py", line 160, in run_endpoint_function
    return await dependant.call(**values)
  File "/Users/zhangjun/PycharmProjects/OSSGPAPI/main.py", line 149, in login
    user = security.authenticate_user(apiusers, form_data.username, form_data.password)
  File "/Users/zhangjun/PycharmProjects/OSSGPAPI/core/security.py", line 69, in authenticate_user
    user = get_user(fake_db, username)
  File "/Users/zhangjun/PycharmProjects/OSSGPAPI/core/security.py", line 64, in get_user
    return UserInDB(**guser)
  File "pydantic/main.py", line 331, in pydantic.main.BaseModel.__init__
pydantic.error_wrappers.ValidationError: 1 validation error for UserInDB
hashed_password
  field required (type=value_error.missing)
[2022-04-27 18:32:14 +0800] [42015] [INFO] Running on https://0.0.0.0:6843 (CTRL + C to quit)
[2022-04-27 18:32:14 +0800] [42015] [INFO] Running on http://0.0.0.0:6880 (CTRL + C to quit)
[2022-04-27 18:32:16 +0800] [42015] [ERROR] Error in ASGI Framework
Traceback (most recent call last):
  File "/Users/zhangjun/PycharmProjects/OSSGPAPI/venv/lib/python3.8/site-packages/hypercorn/trio/task_group.py", line 21, in _handle
    await invoke_asgi(app, scope, receive, send)
  File "/Users/zhangjun/PycharmProjects/OSSGPAPI/venv/lib/python3.8/site-packages/hypercorn/utils.py", line 247, in invoke_asgi
    await app(scope, receive, send)
  File "/Users/zhangjun/PycharmProjects/OSSGPAPI/venv/lib/python3.8/site-packages/fastapi/applications.py", line 261, in __call__
    await super().__call__(scope, receive, send)
  File "/Users/zhangjun/PycharmProjects/OSSGPAPI/venv/lib/python3.8/site-packages/starlette/applications.py", line 112, in __call__
    await self.middleware_stack(scope, receive, send)
  File "/Users/zhangjun/PycharmProjects/OSSGPAPI/venv/lib/python3.8/site-packages/starlette/middleware/errors.py", line 181, in __call__
    raise exc
  File "/Users/zhangjun/PycharmProjects/OSSGPAPI/venv/lib/python3.8/site-packages/starlette/middleware/errors.py", line 159, in __call__
    await self.app(scope, receive, _send)
  File "/Users/zhangjun/PycharmProjects/OSSGPAPI/venv/lib/python3.8/site-packages/starlette/middleware/cors.py", line 92, in __call__
    await self.simple_response(scope, receive, send, request_headers=headers)
  File "/Users/zhangjun/PycharmProjects/OSSGPAPI/venv/lib/python3.8/site-packages/starlette/middleware/cors.py", line 147, in simple_response
    await self.app(scope, receive, send)
  File "/Users/zhangjun/PycharmProjects/OSSGPAPI/venv/lib/python3.8/site-packages/starlette/exceptions.py", line 82, in __call__
    raise exc
  File "/Users/zhangjun/PycharmProjects/OSSGPAPI/venv/lib/python3.8/site-packages/starlette/exceptions.py", line 71, in __call__
    await self.app(scope, receive, sender)
  File "/Users/zhangjun/PycharmProjects/OSSGPAPI/venv/lib/python3.8/site-packages/fastapi/middleware/asyncexitstack.py", line 21, in __call__
    raise e
  File "/Users/zhangjun/PycharmProjects/OSSGPAPI/venv/lib/python3.8/site-packages/fastapi/middleware/asyncexitstack.py", line 18, in __call__
    await self.app(scope, receive, send)
  File "/Users/zhangjun/PycharmProjects/OSSGPAPI/venv/lib/python3.8/site-packages/starlette/routing.py", line 656, in __call__
    await route.handle(scope, receive, send)
  File "/Users/zhangjun/PycharmProjects/OSSGPAPI/venv/lib/python3.8/site-packages/starlette/routing.py", line 259, in handle
    await self.app(scope, receive, send)
  File "/Users/zhangjun/PycharmProjects/OSSGPAPI/venv/lib/python3.8/site-packages/starlette/routing.py", line 61, in app
    response = await func(request)
  File "/Users/zhangjun/PycharmProjects/OSSGPAPI/venv/lib/python3.8/site-packages/fastapi/routing.py", line 227, in app
    raw_response = await run_endpoint_function(
  File "/Users/zhangjun/PycharmProjects/OSSGPAPI/venv/lib/python3.8/site-packages/fastapi/routing.py", line 160, in run_endpoint_function
    return await dependant.call(**values)
  File "/Users/zhangjun/PycharmProjects/OSSGPAPI/main.py", line 149, in login
    user = security.authenticate_user(apiusers, form_data.username, form_data.password)
  File "/Users/zhangjun/PycharmProjects/OSSGPAPI/core/security.py", line 70, in authenticate_user
    user = get_user(fake_db, username)
  File "/Users/zhangjun/PycharmProjects/OSSGPAPI/core/security.py", line 64, in get_user
    log.logger.debug(UserInDB(**guser))
  File "pydantic/main.py", line 331, in pydantic.main.BaseModel.__init__
pydantic.error_wrappers.ValidationError: 1 validation error for UserInDB
hashed_password
  field required (type=value_error.missing)
[2022-04-27 18:32:18 +0800] [42015] [ERROR] Error in ASGI Framework
Traceback (most recent call last):
  File "/Users/zhangjun/PycharmProjects/OSSGPAPI/venv/lib/python3.8/site-packages/hypercorn/trio/task_group.py", line 21, in _handle
    await invoke_asgi(app, scope, receive, send)
  File "/Users/zhangjun/PycharmProjects/OSSGPAPI/venv/lib/python3.8/site-packages/hypercorn/utils.py", line 247, in invoke_asgi
    await app(scope, receive, send)
  File "/Users/zhangjun/PycharmProjects/OSSGPAPI/venv/lib/python3.8/site-packages/fastapi/applications.py", line 261, in __call__
    await super().__call__(scope, receive, send)
  File "/Users/zhangjun/PycharmProjects/OSSGPAPI/venv/lib/python3.8/site-packages/starlette/applications.py", line 112, in __call__
    await self.middleware_stack(scope, receive, send)
  File "/Users/zhangjun/PycharmProjects/OSSGPAPI/venv/lib/python3.8/site-packages/starlette/middleware/errors.py", line 181, in __call__
    raise exc
  File "/Users/zhangjun/PycharmProjects/OSSGPAPI/venv/lib/python3.8/site-packages/starlette/middleware/errors.py", line 159, in __call__
    await self.app(scope, receive, _send)
  File "/Users/zhangjun/PycharmProjects/OSSGPAPI/venv/lib/python3.8/site-packages/starlette/middleware/cors.py", line 92, in __call__
    await self.simple_response(scope, receive, send, request_headers=headers)
  File "/Users/zhangjun/PycharmProjects/OSSGPAPI/venv/lib/python3.8/site-packages/starlette/middleware/cors.py", line 147, in simple_response
    await self.app(scope, receive, send)
  File "/Users/zhangjun/PycharmProjects/OSSGPAPI/venv/lib/python3.8/site-packages/starlette/exceptions.py", line 82, in __call__
    raise exc
  File "/Users/zhangjun/PycharmProjects/OSSGPAPI/venv/lib/python3.8/site-packages/starlette/exceptions.py", line 71, in __call__
    await self.app(scope, receive, sender)
  File "/Users/zhangjun/PycharmProjects/OSSGPAPI/venv/lib/python3.8/site-packages/fastapi/middleware/asyncexitstack.py", line 21, in __call__
    raise e
  File "/Users/zhangjun/PycharmProjects/OSSGPAPI/venv/lib/python3.8/site-packages/fastapi/middleware/asyncexitstack.py", line 18, in __call__
    await self.app(scope, receive, send)
  File "/Users/zhangjun/PycharmProjects/OSSGPAPI/venv/lib/python3.8/site-packages/starlette/routing.py", line 656, in __call__
    await route.handle(scope, receive, send)
  File "/Users/zhangjun/PycharmProjects/OSSGPAPI/venv/lib/python3.8/site-packages/starlette/routing.py", line 259, in handle
    await self.app(scope, receive, send)
  File "/Users/zhangjun/PycharmProjects/OSSGPAPI/venv/lib/python3.8/site-packages/starlette/routing.py", line 61, in app
    response = await func(request)
  File "/Users/zhangjun/PycharmProjects/OSSGPAPI/venv/lib/python3.8/site-packages/fastapi/routing.py", line 227, in app
    raw_response = await run_endpoint_function(
  File "/Users/zhangjun/PycharmProjects/OSSGPAPI/venv/lib/python3.8/site-packages/fastapi/routing.py", line 160, in run_endpoint_function
    return await dependant.call(**values)
  File "/Users/zhangjun/PycharmProjects/OSSGPAPI/main.py", line 149, in login
    user = security.authenticate_user(apiusers, form_data.username, form_data.password)
  File "/Users/zhangjun/PycharmProjects/OSSGPAPI/core/security.py", line 70, in authenticate_user
    user = get_user(fake_db, username)
  File "/Users/zhangjun/PycharmProjects/OSSGPAPI/core/security.py", line 64, in get_user
    log.logger.debug(UserInDB(**guser))
  File "pydantic/main.py", line 331, in pydantic.main.BaseModel.__init__
pydantic.error_wrappers.ValidationError: 1 validation error for UserInDB
hashed_password
  field required (type=value_error.missing)
[2022-04-27 18:32:20 +0800] [42015] [ERROR] Error in ASGI Framework
Traceback (most recent call last):
  File "/Users/zhangjun/PycharmProjects/OSSGPAPI/venv/lib/python3.8/site-packages/hypercorn/trio/task_group.py", line 21, in _handle
    await invoke_asgi(app, scope, receive, send)
  File "/Users/zhangjun/PycharmProjects/OSSGPAPI/venv/lib/python3.8/site-packages/hypercorn/utils.py", line 247, in invoke_asgi
    await app(scope, receive, send)
  File "/Users/zhangjun/PycharmProjects/OSSGPAPI/venv/lib/python3.8/site-packages/fastapi/applications.py", line 261, in __call__
    await super().__call__(scope, receive, send)
  File "/Users/zhangjun/PycharmProjects/OSSGPAPI/venv/lib/python3.8/site-packages/starlette/applications.py", line 112, in __call__
    await self.middleware_stack(scope, receive, send)
  File "/Users/zhangjun/PycharmProjects/OSSGPAPI/venv/lib/python3.8/site-packages/starlette/middleware/errors.py", line 181, in __call__
    raise exc
  File "/Users/zhangjun/PycharmProjects/OSSGPAPI/venv/lib/python3.8/site-packages/starlette/middleware/errors.py", line 159, in __call__
    await self.app(scope, receive, _send)
  File "/Users/zhangjun/PycharmProjects/OSSGPAPI/venv/lib/python3.8/site-packages/starlette/middleware/cors.py", line 92, in __call__
    await self.simple_response(scope, receive, send, request_headers=headers)
  File "/Users/zhangjun/PycharmProjects/OSSGPAPI/venv/lib/python3.8/site-packages/starlette/middleware/cors.py", line 147, in simple_response
    await self.app(scope, receive, send)
  File "/Users/zhangjun/PycharmProjects/OSSGPAPI/venv/lib/python3.8/site-packages/starlette/exceptions.py", line 82, in __call__
    raise exc
  File "/Users/zhangjun/PycharmProjects/OSSGPAPI/venv/lib/python3.8/site-packages/starlette/exceptions.py", line 71, in __call__
    await self.app(scope, receive, sender)
  File "/Users/zhangjun/PycharmProjects/OSSGPAPI/venv/lib/python3.8/site-packages/fastapi/middleware/asyncexitstack.py", line 21, in __call__
    raise e
  File "/Users/zhangjun/PycharmProjects/OSSGPAPI/venv/lib/python3.8/site-packages/fastapi/middleware/asyncexitstack.py", line 18, in __call__
    await self.app(scope, receive, send)
  File "/Users/zhangjun/PycharmProjects/OSSGPAPI/venv/lib/python3.8/site-packages/starlette/routing.py", line 656, in __call__
    await route.handle(scope, receive, send)
  File "/Users/zhangjun/PycharmProjects/OSSGPAPI/venv/lib/python3.8/site-packages/starlette/routing.py", line 259, in handle
    await self.app(scope, receive, send)
  File "/Users/zhangjun/PycharmProjects/OSSGPAPI/venv/lib/python3.8/site-packages/starlette/routing.py", line 61, in app
    response = await func(request)
  File "/Users/zhangjun/PycharmProjects/OSSGPAPI/venv/lib/python3.8/site-packages/fastapi/routing.py", line 227, in app
    raw_response = await run_endpoint_function(
  File "/Users/zhangjun/PycharmProjects/OSSGPAPI/venv/lib/python3.8/site-packages/fastapi/routing.py", line 160, in run_endpoint_function
    return await dependant.call(**values)
  File "/Users/zhangjun/PycharmProjects/OSSGPAPI/main.py", line 149, in login
    user = security.authenticate_user(apiusers, form_data.username, form_data.password)
  File "/Users/zhangjun/PycharmProjects/OSSGPAPI/core/security.py", line 70, in authenticate_user
    user = get_user(fake_db, username)
  File "/Users/zhangjun/PycharmProjects/OSSGPAPI/core/security.py", line 64, in get_user
    log.logger.debug(UserInDB(**guser))
  File "pydantic/main.py", line 331, in pydantic.main.BaseModel.__init__
pydantic.error_wrappers.ValidationError: 1 validation error for UserInDB
hashed_password
  field required (type=value_error.missing)
[2022-04-27 18:32:21 +0800] [42015] [ERROR] Error in ASGI Framework
Traceback (most recent call last):
  File "/Users/zhangjun/PycharmProjects/OSSGPAPI/venv/lib/python3.8/site-packages/hypercorn/trio/task_group.py", line 21, in _handle
    await invoke_asgi(app, scope, receive, send)
  File "/Users/zhangjun/PycharmProjects/OSSGPAPI/venv/lib/python3.8/site-packages/hypercorn/utils.py", line 247, in invoke_asgi
    await app(scope, receive, send)
  File "/Users/zhangjun/PycharmProjects/OSSGPAPI/venv/lib/python3.8/site-packages/fastapi/applications.py", line 261, in __call__
    await super().__call__(scope, receive, send)
  File "/Users/zhangjun/PycharmProjects/OSSGPAPI/venv/lib/python3.8/site-packages/starlette/applications.py", line 112, in __call__
    await self.middleware_stack(scope, receive, send)
  File "/Users/zhangjun/PycharmProjects/OSSGPAPI/venv/lib/python3.8/site-packages/starlette/middleware/errors.py", line 181, in __call__
    raise exc
  File "/Users/zhangjun/PycharmProjects/OSSGPAPI/venv/lib/python3.8/site-packages/starlette/middleware/errors.py", line 159, in __call__
    await self.app(scope, receive, _send)
  File "/Users/zhangjun/PycharmProjects/OSSGPAPI/venv/lib/python3.8/site-packages/starlette/middleware/cors.py", line 92, in __call__
    await self.simple_response(scope, receive, send, request_headers=headers)
  File "/Users/zhangjun/PycharmProjects/OSSGPAPI/venv/lib/python3.8/site-packages/starlette/middleware/cors.py", line 147, in simple_response
    await self.app(scope, receive, send)
  File "/Users/zhangjun/PycharmProjects/OSSGPAPI/venv/lib/python3.8/site-packages/starlette/exceptions.py", line 82, in __call__
    raise exc
  File "/Users/zhangjun/PycharmProjects/OSSGPAPI/venv/lib/python3.8/site-packages/starlette/exceptions.py", line 71, in __call__
    await self.app(scope, receive, sender)
  File "/Users/zhangjun/PycharmProjects/OSSGPAPI/venv/lib/python3.8/site-packages/fastapi/middleware/asyncexitstack.py", line 21, in __call__
    raise e
  File "/Users/zhangjun/PycharmProjects/OSSGPAPI/venv/lib/python3.8/site-packages/fastapi/middleware/asyncexitstack.py", line 18, in __call__
    await self.app(scope, receive, send)
  File "/Users/zhangjun/PycharmProjects/OSSGPAPI/venv/lib/python3.8/site-packages/starlette/routing.py", line 656, in __call__
    await route.handle(scope, receive, send)
  File "/Users/zhangjun/PycharmProjects/OSSGPAPI/venv/lib/python3.8/site-packages/starlette/routing.py", line 259, in handle
    await self.app(scope, receive, send)
  File "/Users/zhangjun/PycharmProjects/OSSGPAPI/venv/lib/python3.8/site-packages/starlette/routing.py", line 61, in app
    response = await func(request)
  File "/Users/zhangjun/PycharmProjects/OSSGPAPI/venv/lib/python3.8/site-packages/fastapi/routing.py", line 227, in app
    raw_response = await run_endpoint_function(
  File "/Users/zhangjun/PycharmProjects/OSSGPAPI/venv/lib/python3.8/site-packages/fastapi/routing.py", line 160, in run_endpoint_function
    return await dependant.call(**values)
  File "/Users/zhangjun/PycharmProjects/OSSGPAPI/main.py", line 149, in login
    user = security.authenticate_user(apiusers, form_data.username, form_data.password)
  File "/Users/zhangjun/PycharmProjects/OSSGPAPI/core/security.py", line 70, in authenticate_user
    user = get_user(fake_db, username)
  File "/Users/zhangjun/PycharmProjects/OSSGPAPI/core/security.py", line 64, in get_user
    log.logger.debug(UserInDB(**guser))
  File "pydantic/main.py", line 331, in pydantic.main.BaseModel.__init__
pydantic.error_wrappers.ValidationError: 1 validation error for UserInDB
hashed_password
  field required (type=value_error.missing)
[2022-04-27 18:32:22 +0800] [42015] [ERROR] Error in ASGI Framework
Traceback (most recent call last):
  File "/Users/zhangjun/PycharmProjects/OSSGPAPI/venv/lib/python3.8/site-packages/hypercorn/trio/task_group.py", line 21, in _handle
    await invoke_asgi(app, scope, receive, send)
  File "/Users/zhangjun/PycharmProjects/OSSGPAPI/venv/lib/python3.8/site-packages/hypercorn/utils.py", line 247, in invoke_asgi
    await app(scope, receive, send)
  File "/Users/zhangjun/PycharmProjects/OSSGPAPI/venv/lib/python3.8/site-packages/fastapi/applications.py", line 261, in __call__
    await super().__call__(scope, receive, send)
  File "/Users/zhangjun/PycharmProjects/OSSGPAPI/venv/lib/python3.8/site-packages/starlette/applications.py", line 112, in __call__
    await self.middleware_stack(scope, receive, send)
  File "/Users/zhangjun/PycharmProjects/OSSGPAPI/venv/lib/python3.8/site-packages/starlette/middleware/errors.py", line 181, in __call__
    raise exc
  File "/Users/zhangjun/PycharmProjects/OSSGPAPI/venv/lib/python3.8/site-packages/starlette/middleware/errors.py", line 159, in __call__
    await self.app(scope, receive, _send)
  File "/Users/zhangjun/PycharmProjects/OSSGPAPI/venv/lib/python3.8/site-packages/starlette/middleware/cors.py", line 92, in __call__
    await self.simple_response(scope, receive, send, request_headers=headers)
  File "/Users/zhangjun/PycharmProjects/OSSGPAPI/venv/lib/python3.8/site-packages/starlette/middleware/cors.py", line 147, in simple_response
    await self.app(scope, receive, send)
  File "/Users/zhangjun/PycharmProjects/OSSGPAPI/venv/lib/python3.8/site-packages/starlette/exceptions.py", line 82, in __call__
    raise exc
  File "/Users/zhangjun/PycharmProjects/OSSGPAPI/venv/lib/python3.8/site-packages/starlette/exceptions.py", line 71, in __call__
    await self.app(scope, receive, sender)
  File "/Users/zhangjun/PycharmProjects/OSSGPAPI/venv/lib/python3.8/site-packages/fastapi/middleware/asyncexitstack.py", line 21, in __call__
    raise e
  File "/Users/zhangjun/PycharmProjects/OSSGPAPI/venv/lib/python3.8/site-packages/fastapi/middleware/asyncexitstack.py", line 18, in __call__
    await self.app(scope, receive, send)
  File "/Users/zhangjun/PycharmProjects/OSSGPAPI/venv/lib/python3.8/site-packages/starlette/routing.py", line 656, in __call__
    await route.handle(scope, receive, send)
  File "/Users/zhangjun/PycharmProjects/OSSGPAPI/venv/lib/python3.8/site-packages/starlette/routing.py", line 259, in handle
    await self.app(scope, receive, send)
  File "/Users/zhangjun/PycharmProjects/OSSGPAPI/venv/lib/python3.8/site-packages/starlette/routing.py", line 61, in app
    response = await func(request)
  File "/Users/zhangjun/PycharmProjects/OSSGPAPI/venv/lib/python3.8/site-packages/fastapi/routing.py", line 227, in app
    raw_response = await run_endpoint_function(
  File "/Users/zhangjun/PycharmProjects/OSSGPAPI/venv/lib/python3.8/site-packages/fastapi/routing.py", line 160, in run_endpoint_function
    return await dependant.call(**values)
  File "/Users/zhangjun/PycharmProjects/OSSGPAPI/main.py", line 149, in login
    user = security.authenticate_user(apiusers, form_data.username, form_data.password)
  File "/Users/zhangjun/PycharmProjects/OSSGPAPI/core/security.py", line 70, in authenticate_user
    user = get_user(fake_db, username)
  File "/Users/zhangjun/PycharmProjects/OSSGPAPI/core/security.py", line 64, in get_user
    log.logger.debug(UserInDB(**guser))
  File "pydantic/main.py", line 331, in pydantic.main.BaseModel.__init__
pydantic.error_wrappers.ValidationError: 1 validation error for UserInDB
hashed_password
  field required (type=value_error.missing)
[2022-04-27 18:32:22 +0800] [42015] [ERROR] Error in ASGI Framework
Traceback (most recent call last):
  File "/Users/zhangjun/PycharmProjects/OSSGPAPI/venv/lib/python3.8/site-packages/hypercorn/trio/task_group.py", line 21, in _handle
    await invoke_asgi(app, scope, receive, send)
  File "/Users/zhangjun/PycharmProjects/OSSGPAPI/venv/lib/python3.8/site-packages/hypercorn/utils.py", line 247, in invoke_asgi
    await app(scope, receive, send)
  File "/Users/zhangjun/PycharmProjects/OSSGPAPI/venv/lib/python3.8/site-packages/fastapi/applications.py", line 261, in __call__
    await super().__call__(scope, receive, send)
  File "/Users/zhangjun/PycharmProjects/OSSGPAPI/venv/lib/python3.8/site-packages/starlette/applications.py", line 112, in __call__
    await self.middleware_stack(scope, receive, send)
  File "/Users/zhangjun/PycharmProjects/OSSGPAPI/venv/lib/python3.8/site-packages/starlette/middleware/errors.py", line 181, in __call__
    raise exc
  File "/Users/zhangjun/PycharmProjects/OSSGPAPI/venv/lib/python3.8/site-packages/starlette/middleware/errors.py", line 159, in __call__
    await self.app(scope, receive, _send)
  File "/Users/zhangjun/PycharmProjects/OSSGPAPI/venv/lib/python3.8/site-packages/starlette/middleware/cors.py", line 92, in __call__
    await self.simple_response(scope, receive, send, request_headers=headers)
  File "/Users/zhangjun/PycharmProjects/OSSGPAPI/venv/lib/python3.8/site-packages/starlette/middleware/cors.py", line 147, in simple_response
    await self.app(scope, receive, send)
  File "/Users/zhangjun/PycharmProjects/OSSGPAPI/venv/lib/python3.8/site-packages/starlette/exceptions.py", line 82, in __call__
    raise exc
  File "/Users/zhangjun/PycharmProjects/OSSGPAPI/venv/lib/python3.8/site-packages/starlette/exceptions.py", line 71, in __call__
    await self.app(scope, receive, sender)
  File "/Users/zhangjun/PycharmProjects/OSSGPAPI/venv/lib/python3.8/site-packages/fastapi/middleware/asyncexitstack.py", line 21, in __call__
    raise e
  File "/Users/zhangjun/PycharmProjects/OSSGPAPI/venv/lib/python3.8/site-packages/fastapi/middleware/asyncexitstack.py", line 18, in __call__
    await self.app(scope, receive, send)
  File "/Users/zhangjun/PycharmProjects/OSSGPAPI/venv/lib/python3.8/site-packages/starlette/routing.py", line 656, in __call__
    await route.handle(scope, receive, send)
  File "/Users/zhangjun/PycharmProjects/OSSGPAPI/venv/lib/python3.8/site-packages/starlette/routing.py", line 259, in handle
    await self.app(scope, receive, send)
  File "/Users/zhangjun/PycharmProjects/OSSGPAPI/venv/lib/python3.8/site-packages/starlette/routing.py", line 61, in app
    response = await func(request)
  File "/Users/zhangjun/PycharmProjects/OSSGPAPI/venv/lib/python3.8/site-packages/fastapi/routing.py", line 227, in app
    raw_response = await run_endpoint_function(
  File "/Users/zhangjun/PycharmProjects/OSSGPAPI/venv/lib/python3.8/site-packages/fastapi/routing.py", line 160, in run_endpoint_function
    return await dependant.call(**values)
  File "/Users/zhangjun/PycharmProjects/OSSGPAPI/main.py", line 149, in login
    user = security.authenticate_user(apiusers, form_data.username, form_data.password)
  File "/Users/zhangjun/PycharmProjects/OSSGPAPI/core/security.py", line 70, in authenticate_user
    user = get_user(fake_db, username)
  File "/Users/zhangjun/PycharmProjects/OSSGPAPI/core/security.py", line 64, in get_user
    log.logger.debug(UserInDB(**guser))
  File "pydantic/main.py", line 331, in pydantic.main.BaseModel.__init__
pydantic.error_wrappers.ValidationError: 1 validation error for UserInDB
hashed_password
  field required (type=value_error.missing)
[2022-04-27 18:32:22 +0800] [42015] [ERROR] Error in ASGI Framework
Traceback (most recent call last):
  File "/Users/zhangjun/PycharmProjects/OSSGPAPI/venv/lib/python3.8/site-packages/hypercorn/trio/task_group.py", line 21, in _handle
    await invoke_asgi(app, scope, receive, send)
  File "/Users/zhangjun/PycharmProjects/OSSGPAPI/venv/lib/python3.8/site-packages/hypercorn/utils.py", line 247, in invoke_asgi
    await app(scope, receive, send)
  File "/Users/zhangjun/PycharmProjects/OSSGPAPI/venv/lib/python3.8/site-packages/fastapi/applications.py", line 261, in __call__
    await super().__call__(scope, receive, send)
  File "/Users/zhangjun/PycharmProjects/OSSGPAPI/venv/lib/python3.8/site-packages/starlette/applications.py", line 112, in __call__
    await self.middleware_stack(scope, receive, send)
  File "/Users/zhangjun/PycharmProjects/OSSGPAPI/venv/lib/python3.8/site-packages/starlette/middleware/errors.py", line 181, in __call__
    raise exc
  File "/Users/zhangjun/PycharmProjects/OSSGPAPI/venv/lib/python3.8/site-packages/starlette/middleware/errors.py", line 159, in __call__
    await self.app(scope, receive, _send)
  File "/Users/zhangjun/PycharmProjects/OSSGPAPI/venv/lib/python3.8/site-packages/starlette/middleware/cors.py", line 92, in __call__
    await self.simple_response(scope, receive, send, request_headers=headers)
  File "/Users/zhangjun/PycharmProjects/OSSGPAPI/venv/lib/python3.8/site-packages/starlette/middleware/cors.py", line 147, in simple_response
    await self.app(scope, receive, send)
  File "/Users/zhangjun/PycharmProjects/OSSGPAPI/venv/lib/python3.8/site-packages/starlette/exceptions.py", line 82, in __call__
    raise exc
  File "/Users/zhangjun/PycharmProjects/OSSGPAPI/venv/lib/python3.8/site-packages/starlette/exceptions.py", line 71, in __call__
    await self.app(scope, receive, sender)
  File "/Users/zhangjun/PycharmProjects/OSSGPAPI/venv/lib/python3.8/site-packages/fastapi/middleware/asyncexitstack.py", line 21, in __call__
    raise e
  File "/Users/zhangjun/PycharmProjects/OSSGPAPI/venv/lib/python3.8/site-packages/fastapi/middleware/asyncexitstack.py", line 18, in __call__
    await self.app(scope, receive, send)
  File "/Users/zhangjun/PycharmProjects/OSSGPAPI/venv/lib/python3.8/site-packages/starlette/routing.py", line 656, in __call__
    await route.handle(scope, receive, send)
  File "/Users/zhangjun/PycharmProjects/OSSGPAPI/venv/lib/python3.8/site-packages/starlette/routing.py", line 259, in handle
    await self.app(scope, receive, send)
  File "/Users/zhangjun/PycharmProjects/OSSGPAPI/venv/lib/python3.8/site-packages/starlette/routing.py", line 61, in app
    response = await func(request)
  File "/Users/zhangjun/PycharmProjects/OSSGPAPI/venv/lib/python3.8/site-packages/fastapi/routing.py", line 227, in app
    raw_response = await run_endpoint_function(
  File "/Users/zhangjun/PycharmProjects/OSSGPAPI/venv/lib/python3.8/site-packages/fastapi/routing.py", line 160, in run_endpoint_function
    return await dependant.call(**values)
  File "/Users/zhangjun/PycharmProjects/OSSGPAPI/main.py", line 149, in login
    user = security.authenticate_user(apiusers, form_data.username, form_data.password)
  File "/Users/zhangjun/PycharmProjects/OSSGPAPI/core/security.py", line 70, in authenticate_user
    user = get_user(fake_db, username)
  File "/Users/zhangjun/PycharmProjects/OSSGPAPI/core/security.py", line 64, in get_user
    log.logger.debug(UserInDB(**guser))
  File "pydantic/main.py", line 331, in pydantic.main.BaseModel.__init__
pydantic.error_wrappers.ValidationError: 1 validation error for UserInDB
hashed_password
  field required (type=value_error.missing)
[2022-04-27 18:32:23 +0800] [42015] [ERROR] Error in ASGI Framework
Traceback (most recent call last):
  File "/Users/zhangjun/PycharmProjects/OSSGPAPI/venv/lib/python3.8/site-packages/hypercorn/trio/task_group.py", line 21, in _handle
    await invoke_asgi(app, scope, receive, send)
  File "/Users/zhangjun/PycharmProjects/OSSGPAPI/venv/lib/python3.8/site-packages/hypercorn/utils.py", line 247, in invoke_asgi
    await app(scope, receive, send)
  File "/Users/zhangjun/PycharmProjects/OSSGPAPI/venv/lib/python3.8/site-packages/fastapi/applications.py", line 261, in __call__
    await super().__call__(scope, receive, send)
  File "/Users/zhangjun/PycharmProjects/OSSGPAPI/venv/lib/python3.8/site-packages/starlette/applications.py", line 112, in __call__
    await self.middleware_stack(scope, receive, send)
  File "/Users/zhangjun/PycharmProjects/OSSGPAPI/venv/lib/python3.8/site-packages/starlette/middleware/errors.py", line 181, in __call__
    raise exc
  File "/Users/zhangjun/PycharmProjects/OSSGPAPI/venv/lib/python3.8/site-packages/starlette/middleware/errors.py", line 159, in __call__
    await self.app(scope, receive, _send)
  File "/Users/zhangjun/PycharmProjects/OSSGPAPI/venv/lib/python3.8/site-packages/starlette/middleware/cors.py", line 92, in __call__
    await self.simple_response(scope, receive, send, request_headers=headers)
  File "/Users/zhangjun/PycharmProjects/OSSGPAPI/venv/lib/python3.8/site-packages/starlette/middleware/cors.py", line 147, in simple_response
    await self.app(scope, receive, send)
  File "/Users/zhangjun/PycharmProjects/OSSGPAPI/venv/lib/python3.8/site-packages/starlette/exceptions.py", line 82, in __call__
    raise exc
  File "/Users/zhangjun/PycharmProjects/OSSGPAPI/venv/lib/python3.8/site-packages/starlette/exceptions.py", line 71, in __call__
    await self.app(scope, receive, sender)
  File "/Users/zhangjun/PycharmProjects/OSSGPAPI/venv/lib/python3.8/site-packages/fastapi/middleware/asyncexitstack.py", line 21, in __call__
    raise e
  File "/Users/zhangjun/PycharmProjects/OSSGPAPI/venv/lib/python3.8/site-packages/fastapi/middleware/asyncexitstack.py", line 18, in __call__
    await self.app(scope, receive, send)
  File "/Users/zhangjun/PycharmProjects/OSSGPAPI/venv/lib/python3.8/site-packages/starlette/routing.py", line 656, in __call__
    await route.handle(scope, receive, send)
  File "/Users/zhangjun/PycharmProjects/OSSGPAPI/venv/lib/python3.8/site-packages/starlette/routing.py", line 259, in handle
    await self.app(scope, receive, send)
  File "/Users/zhangjun/PycharmProjects/OSSGPAPI/venv/lib/python3.8/site-packages/starlette/routing.py", line 61, in app
    response = await func(request)
  File "/Users/zhangjun/PycharmProjects/OSSGPAPI/venv/lib/python3.8/site-packages/fastapi/routing.py", line 227, in app
    raw_response = await run_endpoint_function(
  File "/Users/zhangjun/PycharmProjects/OSSGPAPI/venv/lib/python3.8/site-packages/fastapi/routing.py", line 160, in run_endpoint_function
    return await dependant.call(**values)
  File "/Users/zhangjun/PycharmProjects/OSSGPAPI/main.py", line 149, in login
    user = security.authenticate_user(apiusers, form_data.username, form_data.password)
  File "/Users/zhangjun/PycharmProjects/OSSGPAPI/core/security.py", line 70, in authenticate_user
    user = get_user(fake_db, username)
  File "/Users/zhangjun/PycharmProjects/OSSGPAPI/core/security.py", line 64, in get_user
    log.logger.debug(UserInDB(**guser))
  File "pydantic/main.py", line 331, in pydantic.main.BaseModel.__init__
pydantic.error_wrappers.ValidationError: 1 validation error for UserInDB
hashed_password
  field required (type=value_error.missing)
[2022-04-27 18:32:23 +0800] [42015] [ERROR] Error in ASGI Framework
Traceback (most recent call last):
  File "/Users/zhangjun/PycharmProjects/OSSGPAPI/venv/lib/python3.8/site-packages/hypercorn/trio/task_group.py", line 21, in _handle
    await invoke_asgi(app, scope, receive, send)
  File "/Users/zhangjun/PycharmProjects/OSSGPAPI/venv/lib/python3.8/site-packages/hypercorn/utils.py", line 247, in invoke_asgi
    await app(scope, receive, send)
  File "/Users/zhangjun/PycharmProjects/OSSGPAPI/venv/lib/python3.8/site-packages/fastapi/applications.py", line 261, in __call__
    await super().__call__(scope, receive, send)
  File "/Users/zhangjun/PycharmProjects/OSSGPAPI/venv/lib/python3.8/site-packages/starlette/applications.py", line 112, in __call__
    await self.middleware_stack(scope, receive, send)
  File "/Users/zhangjun/PycharmProjects/OSSGPAPI/venv/lib/python3.8/site-packages/starlette/middleware/errors.py", line 181, in __call__
    raise exc
  File "/Users/zhangjun/PycharmProjects/OSSGPAPI/venv/lib/python3.8/site-packages/starlette/middleware/errors.py", line 159, in __call__
    await self.app(scope, receive, _send)
  File "/Users/zhangjun/PycharmProjects/OSSGPAPI/venv/lib/python3.8/site-packages/starlette/middleware/cors.py", line 92, in __call__
    await self.simple_response(scope, receive, send, request_headers=headers)
  File "/Users/zhangjun/PycharmProjects/OSSGPAPI/venv/lib/python3.8/site-packages/starlette/middleware/cors.py", line 147, in simple_response
    await self.app(scope, receive, send)
  File "/Users/zhangjun/PycharmProjects/OSSGPAPI/venv/lib/python3.8/site-packages/starlette/exceptions.py", line 82, in __call__
    raise exc
  File "/Users/zhangjun/PycharmProjects/OSSGPAPI/venv/lib/python3.8/site-packages/starlette/exceptions.py", line 71, in __call__
    await self.app(scope, receive, sender)
  File "/Users/zhangjun/PycharmProjects/OSSGPAPI/venv/lib/python3.8/site-packages/fastapi/middleware/asyncexitstack.py", line 21, in __call__
    raise e
  File "/Users/zhangjun/PycharmProjects/OSSGPAPI/venv/lib/python3.8/site-packages/fastapi/middleware/asyncexitstack.py", line 18, in __call__
    await self.app(scope, receive, send)
  File "/Users/zhangjun/PycharmProjects/OSSGPAPI/venv/lib/python3.8/site-packages/starlette/routing.py", line 656, in __call__
    await route.handle(scope, receive, send)
  File "/Users/zhangjun/PycharmProjects/OSSGPAPI/venv/lib/python3.8/site-packages/starlette/routing.py", line 259, in handle
    await self.app(scope, receive, send)
  File "/Users/zhangjun/PycharmProjects/OSSGPAPI/venv/lib/python3.8/site-packages/starlette/routing.py", line 61, in app
    response = await func(request)
  File "/Users/zhangjun/PycharmProjects/OSSGPAPI/venv/lib/python3.8/site-packages/fastapi/routing.py", line 227, in app
    raw_response = await run_endpoint_function(
  File "/Users/zhangjun/PycharmProjects/OSSGPAPI/venv/lib/python3.8/site-packages/fastapi/routing.py", line 160, in run_endpoint_function
    return await dependant.call(**values)
  File "/Users/zhangjun/PycharmProjects/OSSGPAPI/main.py", line 149, in login
    user = security.authenticate_user(apiusers, form_data.username, form_data.password)
  File "/Users/zhangjun/PycharmProjects/OSSGPAPI/core/security.py", line 70, in authenticate_user
    user = get_user(fake_db, username)
  File "/Users/zhangjun/PycharmProjects/OSSGPAPI/core/security.py", line 64, in get_user
    log.logger.debug(UserInDB(**guser))
  File "pydantic/main.py", line 331, in pydantic.main.BaseModel.__init__
pydantic.error_wrappers.ValidationError: 1 validation error for UserInDB
hashed_password
  field required (type=value_error.missing)
[2022-04-27 18:32:23 +0800] [42015] [ERROR] Error in ASGI Framework
Traceback (most recent call last):
  File "/Users/zhangjun/PycharmProjects/OSSGPAPI/venv/lib/python3.8/site-packages/hypercorn/trio/task_group.py", line 21, in _handle
    await invoke_asgi(app, scope, receive, send)
  File "/Users/zhangjun/PycharmProjects/OSSGPAPI/venv/lib/python3.8/site-packages/hypercorn/utils.py", line 247, in invoke_asgi
    await app(scope, receive, send)
  File "/Users/zhangjun/PycharmProjects/OSSGPAPI/venv/lib/python3.8/site-packages/fastapi/applications.py", line 261, in __call__
    await super().__call__(scope, receive, send)
  File "/Users/zhangjun/PycharmProjects/OSSGPAPI/venv/lib/python3.8/site-packages/starlette/applications.py", line 112, in __call__
    await self.middleware_stack(scope, receive, send)
  File "/Users/zhangjun/PycharmProjects/OSSGPAPI/venv/lib/python3.8/site-packages/starlette/middleware/errors.py", line 181, in __call__
    raise exc
  File "/Users/zhangjun/PycharmProjects/OSSGPAPI/venv/lib/python3.8/site-packages/starlette/middleware/errors.py", line 159, in __call__
    await self.app(scope, receive, _send)
  File "/Users/zhangjun/PycharmProjects/OSSGPAPI/venv/lib/python3.8/site-packages/starlette/middleware/cors.py", line 92, in __call__
    await self.simple_response(scope, receive, send, request_headers=headers)
  File "/Users/zhangjun/PycharmProjects/OSSGPAPI/venv/lib/python3.8/site-packages/starlette/middleware/cors.py", line 147, in simple_response
    await self.app(scope, receive, send)
  File "/Users/zhangjun/PycharmProjects/OSSGPAPI/venv/lib/python3.8/site-packages/starlette/exceptions.py", line 82, in __call__
    raise exc
  File "/Users/zhangjun/PycharmProjects/OSSGPAPI/venv/lib/python3.8/site-packages/starlette/exceptions.py", line 71, in __call__
    await self.app(scope, receive, sender)
  File "/Users/zhangjun/PycharmProjects/OSSGPAPI/venv/lib/python3.8/site-packages/fastapi/middleware/asyncexitstack.py", line 21, in __call__
    raise e
  File "/Users/zhangjun/PycharmProjects/OSSGPAPI/venv/lib/python3.8/site-packages/fastapi/middleware/asyncexitstack.py", line 18, in __call__
    await self.app(scope, receive, send)
  File "/Users/zhangjun/PycharmProjects/OSSGPAPI/venv/lib/python3.8/site-packages/starlette/routing.py", line 656, in __call__
    await route.handle(scope, receive, send)
  File "/Users/zhangjun/PycharmProjects/OSSGPAPI/venv/lib/python3.8/site-packages/starlette/routing.py", line 259, in handle
    await self.app(scope, receive, send)
  File "/Users/zhangjun/PycharmProjects/OSSGPAPI/venv/lib/python3.8/site-packages/starlette/routing.py", line 61, in app
    response = await func(request)
  File "/Users/zhangjun/PycharmProjects/OSSGPAPI/venv/lib/python3.8/site-packages/fastapi/routing.py", line 227, in app
    raw_response = await run_endpoint_function(
  File "/Users/zhangjun/PycharmProjects/OSSGPAPI/venv/lib/python3.8/site-packages/fastapi/routing.py", line 160, in run_endpoint_function
    return await dependant.call(**values)
  File "/Users/zhangjun/PycharmProjects/OSSGPAPI/main.py", line 149, in login
    user = security.authenticate_user(apiusers, form_data.username, form_data.password)
  File "/Users/zhangjun/PycharmProjects/OSSGPAPI/core/security.py", line 70, in authenticate_user
    user = get_user(fake_db, username)
  File "/Users/zhangjun/PycharmProjects/OSSGPAPI/core/security.py", line 64, in get_user
    log.logger.debug(UserInDB(**guser))
  File "pydantic/main.py", line 331, in pydantic.main.BaseModel.__init__
pydantic.error_wrappers.ValidationError: 1 validation error for UserInDB
hashed_password
  field required (type=value_error.missing)
[2022-04-27 18:32:23 +0800] [42015] [ERROR] Error in ASGI Framework
Traceback (most recent call last):
  File "/Users/zhangjun/PycharmProjects/OSSGPAPI/venv/lib/python3.8/site-packages/hypercorn/trio/task_group.py", line 21, in _handle
    await invoke_asgi(app, scope, receive, send)
  File "/Users/zhangjun/PycharmProjects/OSSGPAPI/venv/lib/python3.8/site-packages/hypercorn/utils.py", line 247, in invoke_asgi
    await app(scope, receive, send)
  File "/Users/zhangjun/PycharmProjects/OSSGPAPI/venv/lib/python3.8/site-packages/fastapi/applications.py", line 261, in __call__
    await super().__call__(scope, receive, send)
  File "/Users/zhangjun/PycharmProjects/OSSGPAPI/venv/lib/python3.8/site-packages/starlette/applications.py", line 112, in __call__
    await self.middleware_stack(scope, receive, send)
  File "/Users/zhangjun/PycharmProjects/OSSGPAPI/venv/lib/python3.8/site-packages/starlette/middleware/errors.py", line 181, in __call__
    raise exc
  File "/Users/zhangjun/PycharmProjects/OSSGPAPI/venv/lib/python3.8/site-packages/starlette/middleware/errors.py", line 159, in __call__
    await self.app(scope, receive, _send)
  File "/Users/zhangjun/PycharmProjects/OSSGPAPI/venv/lib/python3.8/site-packages/starlette/middleware/cors.py", line 92, in __call__
    await self.simple_response(scope, receive, send, request_headers=headers)
  File "/Users/zhangjun/PycharmProjects/OSSGPAPI/venv/lib/python3.8/site-packages/starlette/middleware/cors.py", line 147, in simple_response
    await self.app(scope, receive, send)
  File "/Users/zhangjun/PycharmProjects/OSSGPAPI/venv/lib/python3.8/site-packages/starlette/exceptions.py", line 82, in __call__
    raise exc
  File "/Users/zhangjun/PycharmProjects/OSSGPAPI/venv/lib/python3.8/site-packages/starlette/exceptions.py", line 71, in __call__
    await self.app(scope, receive, sender)
  File "/Users/zhangjun/PycharmProjects/OSSGPAPI/venv/lib/python3.8/site-packages/fastapi/middleware/asyncexitstack.py", line 21, in __call__
    raise e
  File "/Users/zhangjun/PycharmProjects/OSSGPAPI/venv/lib/python3.8/site-packages/fastapi/middleware/asyncexitstack.py", line 18, in __call__
    await self.app(scope, receive, send)
  File "/Users/zhangjun/PycharmProjects/OSSGPAPI/venv/lib/python3.8/site-packages/starlette/routing.py", line 656, in __call__
    await route.handle(scope, receive, send)
  File "/Users/zhangjun/PycharmProjects/OSSGPAPI/venv/lib/python3.8/site-packages/starlette/routing.py", line 259, in handle
    await self.app(scope, receive, send)
  File "/Users/zhangjun/PycharmProjects/OSSGPAPI/venv/lib/python3.8/site-packages/starlette/routing.py", line 61, in app
    response = await func(request)
  File "/Users/zhangjun/PycharmProjects/OSSGPAPI/venv/lib/python3.8/site-packages/fastapi/routing.py", line 227, in app
    raw_response = await run_endpoint_function(
  File "/Users/zhangjun/PycharmProjects/OSSGPAPI/venv/lib/python3.8/site-packages/fastapi/routing.py", line 160, in run_endpoint_function
    return await dependant.call(**values)
  File "/Users/zhangjun/PycharmProjects/OSSGPAPI/main.py", line 149, in login
    user = security.authenticate_user(apiusers, form_data.username, form_data.password)
  File "/Users/zhangjun/PycharmProjects/OSSGPAPI/core/security.py", line 70, in authenticate_user
    user = get_user(fake_db, username)
  File "/Users/zhangjun/PycharmProjects/OSSGPAPI/core/security.py", line 64, in get_user
    log.logger.debug(UserInDB(**guser))
  File "pydantic/main.py", line 331, in pydantic.main.BaseModel.__init__
pydantic.error_wrappers.ValidationError: 1 validation error for UserInDB
hashed_password
  field required (type=value_error.missing)
[2022-04-27 18:32:23 +0800] [42015] [ERROR] Error in ASGI Framework
Traceback (most recent call last):
  File "/Users/zhangjun/PycharmProjects/OSSGPAPI/venv/lib/python3.8/site-packages/hypercorn/trio/task_group.py", line 21, in _handle
    await invoke_asgi(app, scope, receive, send)
  File "/Users/zhangjun/PycharmProjects/OSSGPAPI/venv/lib/python3.8/site-packages/hypercorn/utils.py", line 247, in invoke_asgi
    await app(scope, receive, send)
  File "/Users/zhangjun/PycharmProjects/OSSGPAPI/venv/lib/python3.8/site-packages/fastapi/applications.py", line 261, in __call__
    await super().__call__(scope, receive, send)
  File "/Users/zhangjun/PycharmProjects/OSSGPAPI/venv/lib/python3.8/site-packages/starlette/applications.py", line 112, in __call__
    await self.middleware_stack(scope, receive, send)
  File "/Users/zhangjun/PycharmProjects/OSSGPAPI/venv/lib/python3.8/site-packages/starlette/middleware/errors.py", line 181, in __call__
    raise exc
  File "/Users/zhangjun/PycharmProjects/OSSGPAPI/venv/lib/python3.8/site-packages/starlette/middleware/errors.py", line 159, in __call__
    await self.app(scope, receive, _send)
  File "/Users/zhangjun/PycharmProjects/OSSGPAPI/venv/lib/python3.8/site-packages/starlette/middleware/cors.py", line 92, in __call__
    await self.simple_response(scope, receive, send, request_headers=headers)
  File "/Users/zhangjun/PycharmProjects/OSSGPAPI/venv/lib/python3.8/site-packages/starlette/middleware/cors.py", line 147, in simple_response
    await self.app(scope, receive, send)
  File "/Users/zhangjun/PycharmProjects/OSSGPAPI/venv/lib/python3.8/site-packages/starlette/exceptions.py", line 82, in __call__
    raise exc
  File "/Users/zhangjun/PycharmProjects/OSSGPAPI/venv/lib/python3.8/site-packages/starlette/exceptions.py", line 71, in __call__
    await self.app(scope, receive, sender)
  File "/Users/zhangjun/PycharmProjects/OSSGPAPI/venv/lib/python3.8/site-packages/fastapi/middleware/asyncexitstack.py", line 21, in __call__
    raise e
  File "/Users/zhangjun/PycharmProjects/OSSGPAPI/venv/lib/python3.8/site-packages/fastapi/middleware/asyncexitstack.py", line 18, in __call__
    await self.app(scope, receive, send)
  File "/Users/zhangjun/PycharmProjects/OSSGPAPI/venv/lib/python3.8/site-packages/starlette/routing.py", line 656, in __call__
    await route.handle(scope, receive, send)
  File "/Users/zhangjun/PycharmProjects/OSSGPAPI/venv/lib/python3.8/site-packages/starlette/routing.py", line 259, in handle
    await self.app(scope, receive, send)
  File "/Users/zhangjun/PycharmProjects/OSSGPAPI/venv/lib/python3.8/site-packages/starlette/routing.py", line 61, in app
    response = await func(request)
  File "/Users/zhangjun/PycharmProjects/OSSGPAPI/venv/lib/python3.8/site-packages/fastapi/routing.py", line 227, in app
    raw_response = await run_endpoint_function(
  File "/Users/zhangjun/PycharmProjects/OSSGPAPI/venv/lib/python3.8/site-packages/fastapi/routing.py", line 160, in run_endpoint_function
    return await dependant.call(**values)
  File "/Users/zhangjun/PycharmProjects/OSSGPAPI/main.py", line 149, in login
    user = security.authenticate_user(apiusers, form_data.username, form_data.password)
  File "/Users/zhangjun/PycharmProjects/OSSGPAPI/core/security.py", line 70, in authenticate_user
    user = get_user(fake_db, username)
  File "/Users/zhangjun/PycharmProjects/OSSGPAPI/core/security.py", line 64, in get_user
    log.logger.debug(UserInDB(**guser))
  File "pydantic/main.py", line 331, in pydantic.main.BaseModel.__init__
pydantic.error_wrappers.ValidationError: 1 validation error for UserInDB
hashed_password
  field required (type=value_error.missing)
[2022-04-27 18:32:24 +0800] [42015] [ERROR] Error in ASGI Framework
Traceback (most recent call last):
  File "/Users/zhangjun/PycharmProjects/OSSGPAPI/venv/lib/python3.8/site-packages/hypercorn/trio/task_group.py", line 21, in _handle
    await invoke_asgi(app, scope, receive, send)
  File "/Users/zhangjun/PycharmProjects/OSSGPAPI/venv/lib/python3.8/site-packages/hypercorn/utils.py", line 247, in invoke_asgi
    await app(scope, receive, send)
  File "/Users/zhangjun/PycharmProjects/OSSGPAPI/venv/lib/python3.8/site-packages/fastapi/applications.py", line 261, in __call__
    await super().__call__(scope, receive, send)
  File "/Users/zhangjun/PycharmProjects/OSSGPAPI/venv/lib/python3.8/site-packages/starlette/applications.py", line 112, in __call__
    await self.middleware_stack(scope, receive, send)
  File "/Users/zhangjun/PycharmProjects/OSSGPAPI/venv/lib/python3.8/site-packages/starlette/middleware/errors.py", line 181, in __call__
    raise exc
  File "/Users/zhangjun/PycharmProjects/OSSGPAPI/venv/lib/python3.8/site-packages/starlette/middleware/errors.py", line 159, in __call__
    await self.app(scope, receive, _send)
  File "/Users/zhangjun/PycharmProjects/OSSGPAPI/venv/lib/python3.8/site-packages/starlette/middleware/cors.py", line 92, in __call__
    await self.simple_response(scope, receive, send, request_headers=headers)
  File "/Users/zhangjun/PycharmProjects/OSSGPAPI/venv/lib/python3.8/site-packages/starlette/middleware/cors.py", line 147, in simple_response
    await self.app(scope, receive, send)
  File "/Users/zhangjun/PycharmProjects/OSSGPAPI/venv/lib/python3.8/site-packages/starlette/exceptions.py", line 82, in __call__
    raise exc
  File "/Users/zhangjun/PycharmProjects/OSSGPAPI/venv/lib/python3.8/site-packages/starlette/exceptions.py", line 71, in __call__
    await self.app(scope, receive, sender)
  File "/Users/zhangjun/PycharmProjects/OSSGPAPI/venv/lib/python3.8/site-packages/fastapi/middleware/asyncexitstack.py", line 21, in __call__
    raise e
  File "/Users/zhangjun/PycharmProjects/OSSGPAPI/venv/lib/python3.8/site-packages/fastapi/middleware/asyncexitstack.py", line 18, in __call__
    await self.app(scope, receive, send)
  File "/Users/zhangjun/PycharmProjects/OSSGPAPI/venv/lib/python3.8/site-packages/starlette/routing.py", line 656, in __call__
    await route.handle(scope, receive, send)
  File "/Users/zhangjun/PycharmProjects/OSSGPAPI/venv/lib/python3.8/site-packages/starlette/routing.py", line 259, in handle
    await self.app(scope, receive, send)
  File "/Users/zhangjun/PycharmProjects/OSSGPAPI/venv/lib/python3.8/site-packages/starlette/routing.py", line 61, in app
    response = await func(request)
  File "/Users/zhangjun/PycharmProjects/OSSGPAPI/venv/lib/python3.8/site-packages/fastapi/routing.py", line 227, in app
    raw_response = await run_endpoint_function(
  File "/Users/zhangjun/PycharmProjects/OSSGPAPI/venv/lib/python3.8/site-packages/fastapi/routing.py", line 160, in run_endpoint_function
    return await dependant.call(**values)
  File "/Users/zhangjun/PycharmProjects/OSSGPAPI/main.py", line 149, in login
    user = security.authenticate_user(apiusers, form_data.username, form_data.password)
  File "/Users/zhangjun/PycharmProjects/OSSGPAPI/core/security.py", line 70, in authenticate_user
    user = get_user(fake_db, username)
  File "/Users/zhangjun/PycharmProjects/OSSGPAPI/core/security.py", line 64, in get_user
    log.logger.debug(UserInDB(**guser))
  File "pydantic/main.py", line 331, in pydantic.main.BaseModel.__init__
pydantic.error_wrappers.ValidationError: 1 validation error for UserInDB
hashed_password
  field required (type=value_error.missing)
[2022-04-27 18:32:24 +0800] [42015] [ERROR] Error in ASGI Framework
Traceback (most recent call last):
  File "/Users/zhangjun/PycharmProjects/OSSGPAPI/venv/lib/python3.8/site-packages/hypercorn/trio/task_group.py", line 21, in _handle
    await invoke_asgi(app, scope, receive, send)
  File "/Users/zhangjun/PycharmProjects/OSSGPAPI/venv/lib/python3.8/site-packages/hypercorn/utils.py", line 247, in invoke_asgi
    await app(scope, receive, send)
  File "/Users/zhangjun/PycharmProjects/OSSGPAPI/venv/lib/python3.8/site-packages/fastapi/applications.py", line 261, in __call__
    await super().__call__(scope, receive, send)
  File "/Users/zhangjun/PycharmProjects/OSSGPAPI/venv/lib/python3.8/site-packages/starlette/applications.py", line 112, in __call__
    await self.middleware_stack(scope, receive, send)
  File "/Users/zhangjun/PycharmProjects/OSSGPAPI/venv/lib/python3.8/site-packages/starlette/middleware/errors.py", line 181, in __call__
    raise exc
  File "/Users/zhangjun/PycharmProjects/OSSGPAPI/venv/lib/python3.8/site-packages/starlette/middleware/errors.py", line 159, in __call__
    await self.app(scope, receive, _send)
  File "/Users/zhangjun/PycharmProjects/OSSGPAPI/venv/lib/python3.8/site-packages/starlette/middleware/cors.py", line 92, in __call__
    await self.simple_response(scope, receive, send, request_headers=headers)
  File "/Users/zhangjun/PycharmProjects/OSSGPAPI/venv/lib/python3.8/site-packages/starlette/middleware/cors.py", line 147, in simple_response
    await self.app(scope, receive, send)
  File "/Users/zhangjun/PycharmProjects/OSSGPAPI/venv/lib/python3.8/site-packages/starlette/exceptions.py", line 82, in __call__
    raise exc
  File "/Users/zhangjun/PycharmProjects/OSSGPAPI/venv/lib/python3.8/site-packages/starlette/exceptions.py", line 71, in __call__
    await self.app(scope, receive, sender)
  File "/Users/zhangjun/PycharmProjects/OSSGPAPI/venv/lib/python3.8/site-packages/fastapi/middleware/asyncexitstack.py", line 21, in __call__
    raise e
  File "/Users/zhangjun/PycharmProjects/OSSGPAPI/venv/lib/python3.8/site-packages/fastapi/middleware/asyncexitstack.py", line 18, in __call__
    await self.app(scope, receive, send)
  File "/Users/zhangjun/PycharmProjects/OSSGPAPI/venv/lib/python3.8/site-packages/starlette/routing.py", line 656, in __call__
    await route.handle(scope, receive, send)
  File "/Users/zhangjun/PycharmProjects/OSSGPAPI/venv/lib/python3.8/site-packages/starlette/routing.py", line 259, in handle
    await self.app(scope, receive, send)
  File "/Users/zhangjun/PycharmProjects/OSSGPAPI/venv/lib/python3.8/site-packages/starlette/routing.py", line 61, in app
    response = await func(request)
  File "/Users/zhangjun/PycharmProjects/OSSGPAPI/venv/lib/python3.8/site-packages/fastapi/routing.py", line 227, in app
    raw_response = await run_endpoint_function(
  File "/Users/zhangjun/PycharmProjects/OSSGPAPI/venv/lib/python3.8/site-packages/fastapi/routing.py", line 160, in run_endpoint_function
    return await dependant.call(**values)
  File "/Users/zhangjun/PycharmProjects/OSSGPAPI/main.py", line 149, in login
    user = security.authenticate_user(apiusers, form_data.username, form_data.password)
  File "/Users/zhangjun/PycharmProjects/OSSGPAPI/core/security.py", line 70, in authenticate_user
    user = get_user(fake_db, username)
  File "/Users/zhangjun/PycharmProjects/OSSGPAPI/core/security.py", line 64, in get_user
    log.logger.debug(UserInDB(**guser))
  File "pydantic/main.py", line 331, in pydantic.main.BaseModel.__init__
pydantic.error_wrappers.ValidationError: 1 validation error for UserInDB
hashed_password
  field required (type=value_error.missing)
[2022-04-27 18:32:25 +0800] [42015] [ERROR] Error in ASGI Framework
Traceback (most recent call last):
  File "/Users/zhangjun/PycharmProjects/OSSGPAPI/venv/lib/python3.8/site-packages/hypercorn/trio/task_group.py", line 21, in _handle
    await invoke_asgi(app, scope, receive, send)
  File "/Users/zhangjun/PycharmProjects/OSSGPAPI/venv/lib/python3.8/site-packages/hypercorn/utils.py", line 247, in invoke_asgi
    await app(scope, receive, send)
  File "/Users/zhangjun/PycharmProjects/OSSGPAPI/venv/lib/python3.8/site-packages/fastapi/applications.py", line 261, in __call__
    await super().__call__(scope, receive, send)
  File "/Users/zhangjun/PycharmProjects/OSSGPAPI/venv/lib/python3.8/site-packages/starlette/applications.py", line 112, in __call__
    await self.middleware_stack(scope, receive, send)
  File "/Users/zhangjun/PycharmProjects/OSSGPAPI/venv/lib/python3.8/site-packages/starlette/middleware/errors.py", line 181, in __call__
    raise exc
  File "/Users/zhangjun/PycharmProjects/OSSGPAPI/venv/lib/python3.8/site-packages/starlette/middleware/errors.py", line 159, in __call__
    await self.app(scope, receive, _send)
  File "/Users/zhangjun/PycharmProjects/OSSGPAPI/venv/lib/python3.8/site-packages/starlette/middleware/cors.py", line 92, in __call__
    await self.simple_response(scope, receive, send, request_headers=headers)
  File "/Users/zhangjun/PycharmProjects/OSSGPAPI/venv/lib/python3.8/site-packages/starlette/middleware/cors.py", line 147, in simple_response
    await self.app(scope, receive, send)
  File "/Users/zhangjun/PycharmProjects/OSSGPAPI/venv/lib/python3.8/site-packages/starlette/exceptions.py", line 82, in __call__
    raise exc
  File "/Users/zhangjun/PycharmProjects/OSSGPAPI/venv/lib/python3.8/site-packages/starlette/exceptions.py", line 71, in __call__
    await self.app(scope, receive, sender)
  File "/Users/zhangjun/PycharmProjects/OSSGPAPI/venv/lib/python3.8/site-packages/fastapi/middleware/asyncexitstack.py", line 21, in __call__
    raise e
  File "/Users/zhangjun/PycharmProjects/OSSGPAPI/venv/lib/python3.8/site-packages/fastapi/middleware/asyncexitstack.py", line 18, in __call__
    await self.app(scope, receive, send)
  File "/Users/zhangjun/PycharmProjects/OSSGPAPI/venv/lib/python3.8/site-packages/starlette/routing.py", line 656, in __call__
    await route.handle(scope, receive, send)
  File "/Users/zhangjun/PycharmProjects/OSSGPAPI/venv/lib/python3.8/site-packages/starlette/routing.py", line 259, in handle
    await self.app(scope, receive, send)
  File "/Users/zhangjun/PycharmProjects/OSSGPAPI/venv/lib/python3.8/site-packages/starlette/routing.py", line 61, in app
    response = await func(request)
  File "/Users/zhangjun/PycharmProjects/OSSGPAPI/venv/lib/python3.8/site-packages/fastapi/routing.py", line 227, in app
    raw_response = await run_endpoint_function(
  File "/Users/zhangjun/PycharmProjects/OSSGPAPI/venv/lib/python3.8/site-packages/fastapi/routing.py", line 160, in run_endpoint_function
    return await dependant.call(**values)
  File "/Users/zhangjun/PycharmProjects/OSSGPAPI/main.py", line 149, in login
    user = security.authenticate_user(apiusers, form_data.username, form_data.password)
  File "/Users/zhangjun/PycharmProjects/OSSGPAPI/core/security.py", line 70, in authenticate_user
    user = get_user(fake_db, username)
  File "/Users/zhangjun/PycharmProjects/OSSGPAPI/core/security.py", line 64, in get_user
    log.logger.debug(UserInDB(**guser))
  File "pydantic/main.py", line 331, in pydantic.main.BaseModel.__init__
pydantic.error_wrappers.ValidationError: 1 validation error for UserInDB
hashed_password
  field required (type=value_error.missing)
[2022-04-27 18:33:05 +0800] [42015] [INFO] Running on https://0.0.0.0:6843 (CTRL + C to quit)
[2022-04-27 18:33:05 +0800] [42015] [INFO] Running on http://0.0.0.0:6880 (CTRL + C to quit)
[2022-04-27 18:33:10 +0800] [42015] [ERROR] Error in ASGI Framework
Traceback (most recent call last):
  File "/Users/zhangjun/PycharmProjects/OSSGPAPI/venv/lib/python3.8/site-packages/hypercorn/trio/task_group.py", line 21, in _handle
    await invoke_asgi(app, scope, receive, send)
  File "/Users/zhangjun/PycharmProjects/OSSGPAPI/venv/lib/python3.8/site-packages/hypercorn/utils.py", line 247, in invoke_asgi
    await app(scope, receive, send)
  File "/Users/zhangjun/PycharmProjects/OSSGPAPI/venv/lib/python3.8/site-packages/fastapi/applications.py", line 261, in __call__
    await super().__call__(scope, receive, send)
  File "/Users/zhangjun/PycharmProjects/OSSGPAPI/venv/lib/python3.8/site-packages/starlette/applications.py", line 112, in __call__
    await self.middleware_stack(scope, receive, send)
  File "/Users/zhangjun/PycharmProjects/OSSGPAPI/venv/lib/python3.8/site-packages/starlette/middleware/errors.py", line 181, in __call__
    raise exc
  File "/Users/zhangjun/PycharmProjects/OSSGPAPI/venv/lib/python3.8/site-packages/starlette/middleware/errors.py", line 159, in __call__
    await self.app(scope, receive, _send)
  File "/Users/zhangjun/PycharmProjects/OSSGPAPI/venv/lib/python3.8/site-packages/starlette/middleware/cors.py", line 92, in __call__
    await self.simple_response(scope, receive, send, request_headers=headers)
  File "/Users/zhangjun/PycharmProjects/OSSGPAPI/venv/lib/python3.8/site-packages/starlette/middleware/cors.py", line 147, in simple_response
    await self.app(scope, receive, send)
  File "/Users/zhangjun/PycharmProjects/OSSGPAPI/venv/lib/python3.8/site-packages/starlette/exceptions.py", line 82, in __call__
    raise exc
  File "/Users/zhangjun/PycharmProjects/OSSGPAPI/venv/lib/python3.8/site-packages/starlette/exceptions.py", line 71, in __call__
    await self.app(scope, receive, sender)
  File "/Users/zhangjun/PycharmProjects/OSSGPAPI/venv/lib/python3.8/site-packages/fastapi/middleware/asyncexitstack.py", line 21, in __call__
    raise e
  File "/Users/zhangjun/PycharmProjects/OSSGPAPI/venv/lib/python3.8/site-packages/fastapi/middleware/asyncexitstack.py", line 18, in __call__
    await self.app(scope, receive, send)
  File "/Users/zhangjun/PycharmProjects/OSSGPAPI/venv/lib/python3.8/site-packages/starlette/routing.py", line 656, in __call__
    await route.handle(scope, receive, send)
  File "/Users/zhangjun/PycharmProjects/OSSGPAPI/venv/lib/python3.8/site-packages/starlette/routing.py", line 259, in handle
    await self.app(scope, receive, send)
  File "/Users/zhangjun/PycharmProjects/OSSGPAPI/venv/lib/python3.8/site-packages/starlette/routing.py", line 61, in app
    response = await func(request)
  File "/Users/zhangjun/PycharmProjects/OSSGPAPI/venv/lib/python3.8/site-packages/fastapi/routing.py", line 227, in app
    raw_response = await run_endpoint_function(
  File "/Users/zhangjun/PycharmProjects/OSSGPAPI/venv/lib/python3.8/site-packages/fastapi/routing.py", line 160, in run_endpoint_function
    return await dependant.call(**values)
  File "/Users/zhangjun/PycharmProjects/OSSGPAPI/main.py", line 149, in login
    user = security.authenticate_user(apiusers, form_data.username, form_data.password)
  File "/Users/zhangjun/PycharmProjects/OSSGPAPI/core/security.py", line 70, in authenticate_user
    user = get_user(fake_db, username)
  File "/Users/zhangjun/PycharmProjects/OSSGPAPI/core/security.py", line 64, in get_user
    log.logger.debug(UserInDB(**guser))
  File "pydantic/main.py", line 331, in pydantic.main.BaseModel.__init__
pydantic.error_wrappers.ValidationError: 1 validation error for UserInDB
hashed_password
  field required (type=value_error.missing)
[2022-04-27 18:33:16 +0800] [42090] [INFO] Running on https://0.0.0.0:6843 (CTRL + C to quit)
[2022-04-27 18:33:16 +0800] [42090] [INFO] Running on http://0.0.0.0:6880 (CTRL + C to quit)
[2022-04-27 18:33:17 +0800] [42090] [ERROR] Error in ASGI Framework
Traceback (most recent call last):
  File "/Users/zhangjun/PycharmProjects/OSSGPAPI/venv/lib/python3.8/site-packages/hypercorn/trio/task_group.py", line 21, in _handle
    await invoke_asgi(app, scope, receive, send)
  File "/Users/zhangjun/PycharmProjects/OSSGPAPI/venv/lib/python3.8/site-packages/hypercorn/utils.py", line 247, in invoke_asgi
    await app(scope, receive, send)
  File "/Users/zhangjun/PycharmProjects/OSSGPAPI/venv/lib/python3.8/site-packages/fastapi/applications.py", line 261, in __call__
    await super().__call__(scope, receive, send)
  File "/Users/zhangjun/PycharmProjects/OSSGPAPI/venv/lib/python3.8/site-packages/starlette/applications.py", line 112, in __call__
    await self.middleware_stack(scope, receive, send)
  File "/Users/zhangjun/PycharmProjects/OSSGPAPI/venv/lib/python3.8/site-packages/starlette/middleware/errors.py", line 181, in __call__
    raise exc
  File "/Users/zhangjun/PycharmProjects/OSSGPAPI/venv/lib/python3.8/site-packages/starlette/middleware/errors.py", line 159, in __call__
    await self.app(scope, receive, _send)
  File "/Users/zhangjun/PycharmProjects/OSSGPAPI/venv/lib/python3.8/site-packages/starlette/middleware/cors.py", line 92, in __call__
    await self.simple_response(scope, receive, send, request_headers=headers)
  File "/Users/zhangjun/PycharmProjects/OSSGPAPI/venv/lib/python3.8/site-packages/starlette/middleware/cors.py", line 147, in simple_response
    await self.app(scope, receive, send)
  File "/Users/zhangjun/PycharmProjects/OSSGPAPI/venv/lib/python3.8/site-packages/starlette/exceptions.py", line 82, in __call__
    raise exc
  File "/Users/zhangjun/PycharmProjects/OSSGPAPI/venv/lib/python3.8/site-packages/starlette/exceptions.py", line 71, in __call__
    await self.app(scope, receive, sender)
  File "/Users/zhangjun/PycharmProjects/OSSGPAPI/venv/lib/python3.8/site-packages/fastapi/middleware/asyncexitstack.py", line 21, in __call__
    raise e
  File "/Users/zhangjun/PycharmProjects/OSSGPAPI/venv/lib/python3.8/site-packages/fastapi/middleware/asyncexitstack.py", line 18, in __call__
    await self.app(scope, receive, send)
  File "/Users/zhangjun/PycharmProjects/OSSGPAPI/venv/lib/python3.8/site-packages/starlette/routing.py", line 656, in __call__
    await route.handle(scope, receive, send)
  File "/Users/zhangjun/PycharmProjects/OSSGPAPI/venv/lib/python3.8/site-packages/starlette/routing.py", line 259, in handle
    await self.app(scope, receive, send)
  File "/Users/zhangjun/PycharmProjects/OSSGPAPI/venv/lib/python3.8/site-packages/starlette/routing.py", line 61, in app
    response = await func(request)
  File "/Users/zhangjun/PycharmProjects/OSSGPAPI/venv/lib/python3.8/site-packages/fastapi/routing.py", line 227, in app
    raw_response = await run_endpoint_function(
  File "/Users/zhangjun/PycharmProjects/OSSGPAPI/venv/lib/python3.8/site-packages/fastapi/routing.py", line 160, in run_endpoint_function
    return await dependant.call(**values)
  File "/Users/zhangjun/PycharmProjects/OSSGPAPI/main.py", line 149, in login
    user = security.authenticate_user(apiusers, form_data.username, form_data.password)
  File "/Users/zhangjun/PycharmProjects/OSSGPAPI/core/security.py", line 70, in authenticate_user
    user = get_user(fake_db, username)
  File "/Users/zhangjun/PycharmProjects/OSSGPAPI/core/security.py", line 64, in get_user
    log.logger.debug(UserInDB(**guser))
  File "pydantic/main.py", line 331, in pydantic.main.BaseModel.__init__
pydantic.error_wrappers.ValidationError: 1 validation error for UserInDB
hashed_password
  field required (type=value_error.missing)
[2022-04-27 18:33:52 +0800] [42090] [INFO] Running on https://0.0.0.0:6843 (CTRL + C to quit)
[2022-04-27 18:33:52 +0800] [42090] [INFO] Running on http://0.0.0.0:6880 (CTRL + C to quit)
[2022-04-27 18:33:54 +0800] [42090] [ERROR] Error in ASGI Framework
Traceback (most recent call last):
  File "/Users/zhangjun/PycharmProjects/OSSGPAPI/venv/lib/python3.8/site-packages/hypercorn/trio/task_group.py", line 21, in _handle
    await invoke_asgi(app, scope, receive, send)
  File "/Users/zhangjun/PycharmProjects/OSSGPAPI/venv/lib/python3.8/site-packages/hypercorn/utils.py", line 247, in invoke_asgi
    await app(scope, receive, send)
  File "/Users/zhangjun/PycharmProjects/OSSGPAPI/venv/lib/python3.8/site-packages/fastapi/applications.py", line 261, in __call__
    await super().__call__(scope, receive, send)
  File "/Users/zhangjun/PycharmProjects/OSSGPAPI/venv/lib/python3.8/site-packages/starlette/applications.py", line 112, in __call__
    await self.middleware_stack(scope, receive, send)
  File "/Users/zhangjun/PycharmProjects/OSSGPAPI/venv/lib/python3.8/site-packages/starlette/middleware/errors.py", line 181, in __call__
    raise exc
  File "/Users/zhangjun/PycharmProjects/OSSGPAPI/venv/lib/python3.8/site-packages/starlette/middleware/errors.py", line 159, in __call__
    await self.app(scope, receive, _send)
  File "/Users/zhangjun/PycharmProjects/OSSGPAPI/venv/lib/python3.8/site-packages/starlette/middleware/cors.py", line 92, in __call__
    await self.simple_response(scope, receive, send, request_headers=headers)
  File "/Users/zhangjun/PycharmProjects/OSSGPAPI/venv/lib/python3.8/site-packages/starlette/middleware/cors.py", line 147, in simple_response
    await self.app(scope, receive, send)
  File "/Users/zhangjun/PycharmProjects/OSSGPAPI/venv/lib/python3.8/site-packages/starlette/exceptions.py", line 82, in __call__
    raise exc
  File "/Users/zhangjun/PycharmProjects/OSSGPAPI/venv/lib/python3.8/site-packages/starlette/exceptions.py", line 71, in __call__
    await self.app(scope, receive, sender)
  File "/Users/zhangjun/PycharmProjects/OSSGPAPI/venv/lib/python3.8/site-packages/fastapi/middleware/asyncexitstack.py", line 21, in __call__
    raise e
  File "/Users/zhangjun/PycharmProjects/OSSGPAPI/venv/lib/python3.8/site-packages/fastapi/middleware/asyncexitstack.py", line 18, in __call__
    await self.app(scope, receive, send)
  File "/Users/zhangjun/PycharmProjects/OSSGPAPI/venv/lib/python3.8/site-packages/starlette/routing.py", line 656, in __call__
    await route.handle(scope, receive, send)
  File "/Users/zhangjun/PycharmProjects/OSSGPAPI/venv/lib/python3.8/site-packages/starlette/routing.py", line 259, in handle
    await self.app(scope, receive, send)
  File "/Users/zhangjun/PycharmProjects/OSSGPAPI/venv/lib/python3.8/site-packages/starlette/routing.py", line 61, in app
    response = await func(request)
  File "/Users/zhangjun/PycharmProjects/OSSGPAPI/venv/lib/python3.8/site-packages/fastapi/routing.py", line 227, in app
    raw_response = await run_endpoint_function(
  File "/Users/zhangjun/PycharmProjects/OSSGPAPI/venv/lib/python3.8/site-packages/fastapi/routing.py", line 160, in run_endpoint_function
    return await dependant.call(**values)
  File "/Users/zhangjun/PycharmProjects/OSSGPAPI/main.py", line 149, in login
    user = security.authenticate_user(apiusers, form_data.username, form_data.password)
  File "/Users/zhangjun/PycharmProjects/OSSGPAPI/core/security.py", line 70, in authenticate_user
    user = get_user(fake_db, username)
  File "/Users/zhangjun/PycharmProjects/OSSGPAPI/core/security.py", line 64, in get_user
    log.logger.debug(UserInDB(**guser))
  File "pydantic/main.py", line 331, in pydantic.main.BaseModel.__init__
pydantic.error_wrappers.ValidationError: 1 validation error for UserInDB
hashed_password
  field required (type=value_error.missing)
[2022-04-27 18:34:21 +0800] [42090] [INFO] Running on https://0.0.0.0:6843 (CTRL + C to quit)
[2022-04-27 18:34:21 +0800] [42090] [INFO] Running on http://0.0.0.0:6880 (CTRL + C to quit)
[2022-04-27 18:34:23 +0800] [42090] [ERROR] Error in ASGI Framework
Traceback (most recent call last):
  File "/Users/zhangjun/PycharmProjects/OSSGPAPI/venv/lib/python3.8/site-packages/hypercorn/trio/task_group.py", line 21, in _handle
    await invoke_asgi(app, scope, receive, send)
  File "/Users/zhangjun/PycharmProjects/OSSGPAPI/venv/lib/python3.8/site-packages/hypercorn/utils.py", line 247, in invoke_asgi
    await app(scope, receive, send)
  File "/Users/zhangjun/PycharmProjects/OSSGPAPI/venv/lib/python3.8/site-packages/fastapi/applications.py", line 261, in __call__
    await super().__call__(scope, receive, send)
  File "/Users/zhangjun/PycharmProjects/OSSGPAPI/venv/lib/python3.8/site-packages/starlette/applications.py", line 112, in __call__
    await self.middleware_stack(scope, receive, send)
  File "/Users/zhangjun/PycharmProjects/OSSGPAPI/venv/lib/python3.8/site-packages/starlette/middleware/errors.py", line 181, in __call__
    raise exc
  File "/Users/zhangjun/PycharmProjects/OSSGPAPI/venv/lib/python3.8/site-packages/starlette/middleware/errors.py", line 159, in __call__
    await self.app(scope, receive, _send)
  File "/Users/zhangjun/PycharmProjects/OSSGPAPI/venv/lib/python3.8/site-packages/starlette/middleware/cors.py", line 92, in __call__
    await self.simple_response(scope, receive, send, request_headers=headers)
  File "/Users/zhangjun/PycharmProjects/OSSGPAPI/venv/lib/python3.8/site-packages/starlette/middleware/cors.py", line 147, in simple_response
    await self.app(scope, receive, send)
  File "/Users/zhangjun/PycharmProjects/OSSGPAPI/venv/lib/python3.8/site-packages/starlette/exceptions.py", line 82, in __call__
    raise exc
  File "/Users/zhangjun/PycharmProjects/OSSGPAPI/venv/lib/python3.8/site-packages/starlette/exceptions.py", line 71, in __call__
    await self.app(scope, receive, sender)
  File "/Users/zhangjun/PycharmProjects/OSSGPAPI/venv/lib/python3.8/site-packages/fastapi/middleware/asyncexitstack.py", line 21, in __call__
    raise e
  File "/Users/zhangjun/PycharmProjects/OSSGPAPI/venv/lib/python3.8/site-packages/fastapi/middleware/asyncexitstack.py", line 18, in __call__
    await self.app(scope, receive, send)
  File "/Users/zhangjun/PycharmProjects/OSSGPAPI/venv/lib/python3.8/site-packages/starlette/routing.py", line 656, in __call__
    await route.handle(scope, receive, send)
  File "/Users/zhangjun/PycharmProjects/OSSGPAPI/venv/lib/python3.8/site-packages/starlette/routing.py", line 259, in handle
    await self.app(scope, receive, send)
  File "/Users/zhangjun/PycharmProjects/OSSGPAPI/venv/lib/python3.8/site-packages/starlette/routing.py", line 61, in app
    response = await func(request)
  File "/Users/zhangjun/PycharmProjects/OSSGPAPI/venv/lib/python3.8/site-packages/fastapi/routing.py", line 227, in app
    raw_response = await run_endpoint_function(
  File "/Users/zhangjun/PycharmProjects/OSSGPAPI/venv/lib/python3.8/site-packages/fastapi/routing.py", line 160, in run_endpoint_function
    return await dependant.call(**values)
  File "/Users/zhangjun/PycharmProjects/OSSGPAPI/main.py", line 149, in login
    user = security.authenticate_user(apiusers, form_data.username, form_data.password)
  File "/Users/zhangjun/PycharmProjects/OSSGPAPI/core/security.py", line 70, in authenticate_user
    user = get_user(fake_db, username)
  File "/Users/zhangjun/PycharmProjects/OSSGPAPI/core/security.py", line 64, in get_user
    log.logger.debug(UserInDB(**guser))
  File "pydantic/main.py", line 331, in pydantic.main.BaseModel.__init__
pydantic.error_wrappers.ValidationError: 1 validation error for UserInDB
hashed_password
  field required (type=value_error.missing)
[2022-04-27 18:34:51 +0800] [42090] [INFO] Running on https://0.0.0.0:6843 (CTRL + C to quit)
[2022-04-27 18:34:51 +0800] [42090] [INFO] Running on http://0.0.0.0:6880 (CTRL + C to quit)
[2022-04-27 18:34:52 +0800] [42090] [ERROR] Error in ASGI Framework
Traceback (most recent call last):
  File "/Users/zhangjun/PycharmProjects/OSSGPAPI/venv/lib/python3.8/site-packages/hypercorn/trio/task_group.py", line 21, in _handle
    await invoke_asgi(app, scope, receive, send)
  File "/Users/zhangjun/PycharmProjects/OSSGPAPI/venv/lib/python3.8/site-packages/hypercorn/utils.py", line 247, in invoke_asgi
    await app(scope, receive, send)
  File "/Users/zhangjun/PycharmProjects/OSSGPAPI/venv/lib/python3.8/site-packages/fastapi/applications.py", line 261, in __call__
    await super().__call__(scope, receive, send)
  File "/Users/zhangjun/PycharmProjects/OSSGPAPI/venv/lib/python3.8/site-packages/starlette/applications.py", line 112, in __call__
    await self.middleware_stack(scope, receive, send)
  File "/Users/zhangjun/PycharmProjects/OSSGPAPI/venv/lib/python3.8/site-packages/starlette/middleware/errors.py", line 181, in __call__
    raise exc
  File "/Users/zhangjun/PycharmProjects/OSSGPAPI/venv/lib/python3.8/site-packages/starlette/middleware/errors.py", line 159, in __call__
    await self.app(scope, receive, _send)
  File "/Users/zhangjun/PycharmProjects/OSSGPAPI/venv/lib/python3.8/site-packages/starlette/middleware/cors.py", line 92, in __call__
    await self.simple_response(scope, receive, send, request_headers=headers)
  File "/Users/zhangjun/PycharmProjects/OSSGPAPI/venv/lib/python3.8/site-packages/starlette/middleware/cors.py", line 147, in simple_response
    await self.app(scope, receive, send)
  File "/Users/zhangjun/PycharmProjects/OSSGPAPI/venv/lib/python3.8/site-packages/starlette/exceptions.py", line 82, in __call__
    raise exc
  File "/Users/zhangjun/PycharmProjects/OSSGPAPI/venv/lib/python3.8/site-packages/starlette/exceptions.py", line 71, in __call__
    await self.app(scope, receive, sender)
  File "/Users/zhangjun/PycharmProjects/OSSGPAPI/venv/lib/python3.8/site-packages/fastapi/middleware/asyncexitstack.py", line 21, in __call__
    raise e
  File "/Users/zhangjun/PycharmProjects/OSSGPAPI/venv/lib/python3.8/site-packages/fastapi/middleware/asyncexitstack.py", line 18, in __call__
    await self.app(scope, receive, send)
  File "/Users/zhangjun/PycharmProjects/OSSGPAPI/venv/lib/python3.8/site-packages/starlette/routing.py", line 656, in __call__
    await route.handle(scope, receive, send)
  File "/Users/zhangjun/PycharmProjects/OSSGPAPI/venv/lib/python3.8/site-packages/starlette/routing.py", line 259, in handle
    await self.app(scope, receive, send)
  File "/Users/zhangjun/PycharmProjects/OSSGPAPI/venv/lib/python3.8/site-packages/starlette/routing.py", line 61, in app
    response = await func(request)
  File "/Users/zhangjun/PycharmProjects/OSSGPAPI/venv/lib/python3.8/site-packages/fastapi/routing.py", line 227, in app
    raw_response = await run_endpoint_function(
  File "/Users/zhangjun/PycharmProjects/OSSGPAPI/venv/lib/python3.8/site-packages/fastapi/routing.py", line 160, in run_endpoint_function
    return await dependant.call(**values)
  File "/Users/zhangjun/PycharmProjects/OSSGPAPI/main.py", line 149, in login
    user = security.authenticate_user(apiusers, form_data.username, form_data.password)
  File "/Users/zhangjun/PycharmProjects/OSSGPAPI/core/security.py", line 71, in authenticate_user
    user = get_user(fake_db, username)
  File "/Users/zhangjun/PycharmProjects/OSSGPAPI/core/security.py", line 65, in get_user
    log.logger.debug(UserInDB(**guser))
  File "pydantic/main.py", line 331, in pydantic.main.BaseModel.__init__
pydantic.error_wrappers.ValidationError: 1 validation error for UserInDB
hashed_password
  field required (type=value_error.missing)
[2022-04-27 18:35:21 +0800] [42090] [INFO] Running on https://0.0.0.0:6843 (CTRL + C to quit)
[2022-04-27 18:35:21 +0800] [42090] [INFO] Running on http://0.0.0.0:6880 (CTRL + C to quit)
[2022-04-27 18:35:29 +0800] [42090] [ERROR] Error in ASGI Framework
Traceback (most recent call last):
  File "/Users/zhangjun/PycharmProjects/OSSGPAPI/venv/lib/python3.8/site-packages/hypercorn/trio/task_group.py", line 21, in _handle
    await invoke_asgi(app, scope, receive, send)
  File "/Users/zhangjun/PycharmProjects/OSSGPAPI/venv/lib/python3.8/site-packages/hypercorn/utils.py", line 247, in invoke_asgi
    await app(scope, receive, send)
  File "/Users/zhangjun/PycharmProjects/OSSGPAPI/venv/lib/python3.8/site-packages/fastapi/applications.py", line 261, in __call__
    await super().__call__(scope, receive, send)
  File "/Users/zhangjun/PycharmProjects/OSSGPAPI/venv/lib/python3.8/site-packages/starlette/applications.py", line 112, in __call__
    await self.middleware_stack(scope, receive, send)
  File "/Users/zhangjun/PycharmProjects/OSSGPAPI/venv/lib/python3.8/site-packages/starlette/middleware/errors.py", line 181, in __call__
    raise exc
  File "/Users/zhangjun/PycharmProjects/OSSGPAPI/venv/lib/python3.8/site-packages/starlette/middleware/errors.py", line 159, in __call__
    await self.app(scope, receive, _send)
  File "/Users/zhangjun/PycharmProjects/OSSGPAPI/venv/lib/python3.8/site-packages/starlette/middleware/cors.py", line 92, in __call__
    await self.simple_response(scope, receive, send, request_headers=headers)
  File "/Users/zhangjun/PycharmProjects/OSSGPAPI/venv/lib/python3.8/site-packages/starlette/middleware/cors.py", line 147, in simple_response
    await self.app(scope, receive, send)
  File "/Users/zhangjun/PycharmProjects/OSSGPAPI/venv/lib/python3.8/site-packages/starlette/exceptions.py", line 82, in __call__
    raise exc
  File "/Users/zhangjun/PycharmProjects/OSSGPAPI/venv/lib/python3.8/site-packages/starlette/exceptions.py", line 71, in __call__
    await self.app(scope, receive, sender)
  File "/Users/zhangjun/PycharmProjects/OSSGPAPI/venv/lib/python3.8/site-packages/fastapi/middleware/asyncexitstack.py", line 21, in __call__
    raise e
  File "/Users/zhangjun/PycharmProjects/OSSGPAPI/venv/lib/python3.8/site-packages/fastapi/middleware/asyncexitstack.py", line 18, in __call__
    await self.app(scope, receive, send)
  File "/Users/zhangjun/PycharmProjects/OSSGPAPI/venv/lib/python3.8/site-packages/starlette/routing.py", line 656, in __call__
    await route.handle(scope, receive, send)
  File "/Users/zhangjun/PycharmProjects/OSSGPAPI/venv/lib/python3.8/site-packages/starlette/routing.py", line 259, in handle
    await self.app(scope, receive, send)
  File "/Users/zhangjun/PycharmProjects/OSSGPAPI/venv/lib/python3.8/site-packages/starlette/routing.py", line 61, in app
    response = await func(request)
  File "/Users/zhangjun/PycharmProjects/OSSGPAPI/venv/lib/python3.8/site-packages/fastapi/routing.py", line 227, in app
    raw_response = await run_endpoint_function(
  File "/Users/zhangjun/PycharmProjects/OSSGPAPI/venv/lib/python3.8/site-packages/fastapi/routing.py", line 160, in run_endpoint_function
    return await dependant.call(**values)
  File "/Users/zhangjun/PycharmProjects/OSSGPAPI/main.py", line 149, in login
    user = security.authenticate_user(apiusers, form_data.username, form_data.password)
  File "/Users/zhangjun/PycharmProjects/OSSGPAPI/core/security.py", line 72, in authenticate_user
    user = get_user(fake_db, username)
  File "/Users/zhangjun/PycharmProjects/OSSGPAPI/core/security.py", line 64, in get_user
    log.logger.debug(**guser)
TypeError: debug() missing 1 required positional argument: '_Logger__message'
[2022-04-27 18:35:34 +0800] [42090] [ERROR] Error in ASGI Framework
Traceback (most recent call last):
  File "/Users/zhangjun/PycharmProjects/OSSGPAPI/venv/lib/python3.8/site-packages/hypercorn/trio/task_group.py", line 21, in _handle
    await invoke_asgi(app, scope, receive, send)
  File "/Users/zhangjun/PycharmProjects/OSSGPAPI/venv/lib/python3.8/site-packages/hypercorn/utils.py", line 247, in invoke_asgi
    await app(scope, receive, send)
  File "/Users/zhangjun/PycharmProjects/OSSGPAPI/venv/lib/python3.8/site-packages/fastapi/applications.py", line 261, in __call__
    await super().__call__(scope, receive, send)
  File "/Users/zhangjun/PycharmProjects/OSSGPAPI/venv/lib/python3.8/site-packages/starlette/applications.py", line 112, in __call__
    await self.middleware_stack(scope, receive, send)
  File "/Users/zhangjun/PycharmProjects/OSSGPAPI/venv/lib/python3.8/site-packages/starlette/middleware/errors.py", line 181, in __call__
    raise exc
  File "/Users/zhangjun/PycharmProjects/OSSGPAPI/venv/lib/python3.8/site-packages/starlette/middleware/errors.py", line 159, in __call__
    await self.app(scope, receive, _send)
  File "/Users/zhangjun/PycharmProjects/OSSGPAPI/venv/lib/python3.8/site-packages/starlette/middleware/cors.py", line 92, in __call__
    await self.simple_response(scope, receive, send, request_headers=headers)
  File "/Users/zhangjun/PycharmProjects/OSSGPAPI/venv/lib/python3.8/site-packages/starlette/middleware/cors.py", line 147, in simple_response
    await self.app(scope, receive, send)
  File "/Users/zhangjun/PycharmProjects/OSSGPAPI/venv/lib/python3.8/site-packages/starlette/exceptions.py", line 82, in __call__
    raise exc
  File "/Users/zhangjun/PycharmProjects/OSSGPAPI/venv/lib/python3.8/site-packages/starlette/exceptions.py", line 71, in __call__
    await self.app(scope, receive, sender)
  File "/Users/zhangjun/PycharmProjects/OSSGPAPI/venv/lib/python3.8/site-packages/fastapi/middleware/asyncexitstack.py", line 21, in __call__
    raise e
  File "/Users/zhangjun/PycharmProjects/OSSGPAPI/venv/lib/python3.8/site-packages/fastapi/middleware/asyncexitstack.py", line 18, in __call__
    await self.app(scope, receive, send)
  File "/Users/zhangjun/PycharmProjects/OSSGPAPI/venv/lib/python3.8/site-packages/starlette/routing.py", line 656, in __call__
    await route.handle(scope, receive, send)
  File "/Users/zhangjun/PycharmProjects/OSSGPAPI/venv/lib/python3.8/site-packages/starlette/routing.py", line 259, in handle
    await self.app(scope, receive, send)
  File "/Users/zhangjun/PycharmProjects/OSSGPAPI/venv/lib/python3.8/site-packages/starlette/routing.py", line 61, in app
    response = await func(request)
  File "/Users/zhangjun/PycharmProjects/OSSGPAPI/venv/lib/python3.8/site-packages/fastapi/routing.py", line 227, in app
    raw_response = await run_endpoint_function(
  File "/Users/zhangjun/PycharmProjects/OSSGPAPI/venv/lib/python3.8/site-packages/fastapi/routing.py", line 160, in run_endpoint_function
    return await dependant.call(**values)
  File "/Users/zhangjun/PycharmProjects/OSSGPAPI/main.py", line 149, in login
    user = security.authenticate_user(apiusers, form_data.username, form_data.password)
  File "/Users/zhangjun/PycharmProjects/OSSGPAPI/core/security.py", line 72, in authenticate_user
    user = get_user(fake_db, username)
  File "/Users/zhangjun/PycharmProjects/OSSGPAPI/core/security.py", line 64, in get_user
    log.logger.debug(**guser)
TypeError: debug() missing 1 required positional argument: '_Logger__message'
[2022-04-27 18:35:35 +0800] [42090] [ERROR] Error in ASGI Framework
Traceback (most recent call last):
  File "/Users/zhangjun/PycharmProjects/OSSGPAPI/venv/lib/python3.8/site-packages/hypercorn/trio/task_group.py", line 21, in _handle
    await invoke_asgi(app, scope, receive, send)
  File "/Users/zhangjun/PycharmProjects/OSSGPAPI/venv/lib/python3.8/site-packages/hypercorn/utils.py", line 247, in invoke_asgi
    await app(scope, receive, send)
  File "/Users/zhangjun/PycharmProjects/OSSGPAPI/venv/lib/python3.8/site-packages/fastapi/applications.py", line 261, in __call__
    await super().__call__(scope, receive, send)
  File "/Users/zhangjun/PycharmProjects/OSSGPAPI/venv/lib/python3.8/site-packages/starlette/applications.py", line 112, in __call__
    await self.middleware_stack(scope, receive, send)
  File "/Users/zhangjun/PycharmProjects/OSSGPAPI/venv/lib/python3.8/site-packages/starlette/middleware/errors.py", line 181, in __call__
    raise exc
  File "/Users/zhangjun/PycharmProjects/OSSGPAPI/venv/lib/python3.8/site-packages/starlette/middleware/errors.py", line 159, in __call__
    await self.app(scope, receive, _send)
  File "/Users/zhangjun/PycharmProjects/OSSGPAPI/venv/lib/python3.8/site-packages/starlette/middleware/cors.py", line 92, in __call__
    await self.simple_response(scope, receive, send, request_headers=headers)
  File "/Users/zhangjun/PycharmProjects/OSSGPAPI/venv/lib/python3.8/site-packages/starlette/middleware/cors.py", line 147, in simple_response
    await self.app(scope, receive, send)
  File "/Users/zhangjun/PycharmProjects/OSSGPAPI/venv/lib/python3.8/site-packages/starlette/exceptions.py", line 82, in __call__
    raise exc
  File "/Users/zhangjun/PycharmProjects/OSSGPAPI/venv/lib/python3.8/site-packages/starlette/exceptions.py", line 71, in __call__
    await self.app(scope, receive, sender)
  File "/Users/zhangjun/PycharmProjects/OSSGPAPI/venv/lib/python3.8/site-packages/fastapi/middleware/asyncexitstack.py", line 21, in __call__
    raise e
  File "/Users/zhangjun/PycharmProjects/OSSGPAPI/venv/lib/python3.8/site-packages/fastapi/middleware/asyncexitstack.py", line 18, in __call__
    await self.app(scope, receive, send)
  File "/Users/zhangjun/PycharmProjects/OSSGPAPI/venv/lib/python3.8/site-packages/starlette/routing.py", line 656, in __call__
    await route.handle(scope, receive, send)
  File "/Users/zhangjun/PycharmProjects/OSSGPAPI/venv/lib/python3.8/site-packages/starlette/routing.py", line 259, in handle
    await self.app(scope, receive, send)
  File "/Users/zhangjun/PycharmProjects/OSSGPAPI/venv/lib/python3.8/site-packages/starlette/routing.py", line 61, in app
    response = await func(request)
  File "/Users/zhangjun/PycharmProjects/OSSGPAPI/venv/lib/python3.8/site-packages/fastapi/routing.py", line 227, in app
    raw_response = await run_endpoint_function(
  File "/Users/zhangjun/PycharmProjects/OSSGPAPI/venv/lib/python3.8/site-packages/fastapi/routing.py", line 160, in run_endpoint_function
    return await dependant.call(**values)
  File "/Users/zhangjun/PycharmProjects/OSSGPAPI/main.py", line 149, in login
    user = security.authenticate_user(apiusers, form_data.username, form_data.password)
  File "/Users/zhangjun/PycharmProjects/OSSGPAPI/core/security.py", line 72, in authenticate_user
    user = get_user(fake_db, username)
  File "/Users/zhangjun/PycharmProjects/OSSGPAPI/core/security.py", line 64, in get_user
    log.logger.debug(**guser)
TypeError: debug() missing 1 required positional argument: '_Logger__message'
[2022-04-27 18:35:40 +0800] [42184] [INFO] Running on https://0.0.0.0:6843 (CTRL + C to quit)
[2022-04-27 18:35:40 +0800] [42184] [INFO] Running on http://0.0.0.0:6880 (CTRL + C to quit)
[2022-04-27 18:35:42 +0800] [42184] [ERROR] Error in ASGI Framework
Traceback (most recent call last):
  File "/Users/zhangjun/PycharmProjects/OSSGPAPI/venv/lib/python3.8/site-packages/hypercorn/trio/task_group.py", line 21, in _handle
    await invoke_asgi(app, scope, receive, send)
  File "/Users/zhangjun/PycharmProjects/OSSGPAPI/venv/lib/python3.8/site-packages/hypercorn/utils.py", line 247, in invoke_asgi
    await app(scope, receive, send)
  File "/Users/zhangjun/PycharmProjects/OSSGPAPI/venv/lib/python3.8/site-packages/fastapi/applications.py", line 261, in __call__
    await super().__call__(scope, receive, send)
  File "/Users/zhangjun/PycharmProjects/OSSGPAPI/venv/lib/python3.8/site-packages/starlette/applications.py", line 112, in __call__
    await self.middleware_stack(scope, receive, send)
  File "/Users/zhangjun/PycharmProjects/OSSGPAPI/venv/lib/python3.8/site-packages/starlette/middleware/errors.py", line 181, in __call__
    raise exc
  File "/Users/zhangjun/PycharmProjects/OSSGPAPI/venv/lib/python3.8/site-packages/starlette/middleware/errors.py", line 159, in __call__
    await self.app(scope, receive, _send)
  File "/Users/zhangjun/PycharmProjects/OSSGPAPI/venv/lib/python3.8/site-packages/starlette/middleware/cors.py", line 92, in __call__
    await self.simple_response(scope, receive, send, request_headers=headers)
  File "/Users/zhangjun/PycharmProjects/OSSGPAPI/venv/lib/python3.8/site-packages/starlette/middleware/cors.py", line 147, in simple_response
    await self.app(scope, receive, send)
  File "/Users/zhangjun/PycharmProjects/OSSGPAPI/venv/lib/python3.8/site-packages/starlette/exceptions.py", line 82, in __call__
    raise exc
  File "/Users/zhangjun/PycharmProjects/OSSGPAPI/venv/lib/python3.8/site-packages/starlette/exceptions.py", line 71, in __call__
    await self.app(scope, receive, sender)
  File "/Users/zhangjun/PycharmProjects/OSSGPAPI/venv/lib/python3.8/site-packages/fastapi/middleware/asyncexitstack.py", line 21, in __call__
    raise e
  File "/Users/zhangjun/PycharmProjects/OSSGPAPI/venv/lib/python3.8/site-packages/fastapi/middleware/asyncexitstack.py", line 18, in __call__
    await self.app(scope, receive, send)
  File "/Users/zhangjun/PycharmProjects/OSSGPAPI/venv/lib/python3.8/site-packages/starlette/routing.py", line 656, in __call__
    await route.handle(scope, receive, send)
  File "/Users/zhangjun/PycharmProjects/OSSGPAPI/venv/lib/python3.8/site-packages/starlette/routing.py", line 259, in handle
    await self.app(scope, receive, send)
  File "/Users/zhangjun/PycharmProjects/OSSGPAPI/venv/lib/python3.8/site-packages/starlette/routing.py", line 61, in app
    response = await func(request)
  File "/Users/zhangjun/PycharmProjects/OSSGPAPI/venv/lib/python3.8/site-packages/fastapi/routing.py", line 227, in app
    raw_response = await run_endpoint_function(
  File "/Users/zhangjun/PycharmProjects/OSSGPAPI/venv/lib/python3.8/site-packages/fastapi/routing.py", line 160, in run_endpoint_function
    return await dependant.call(**values)
  File "/Users/zhangjun/PycharmProjects/OSSGPAPI/main.py", line 149, in login
    user = security.authenticate_user(apiusers, form_data.username, form_data.password)
  File "/Users/zhangjun/PycharmProjects/OSSGPAPI/core/security.py", line 72, in authenticate_user
    user = get_user(fake_db, username)
  File "/Users/zhangjun/PycharmProjects/OSSGPAPI/core/security.py", line 64, in get_user
    log.logger.debug(**guser)
TypeError: debug() missing 1 required positional argument: '_Logger__message'
[2022-04-27 18:37:21 +0800] [42184] [INFO] Running on https://0.0.0.0:6843 (CTRL + C to quit)
[2022-04-27 18:37:21 +0800] [42184] [INFO] Running on http://0.0.0.0:6880 (CTRL + C to quit)
[2022-04-27 18:37:47 +0800] [42184] [INFO] Running on https://0.0.0.0:6843 (CTRL + C to quit)
[2022-04-27 18:37:47 +0800] [42184] [INFO] Running on http://0.0.0.0:6880 (CTRL + C to quit)
[2022-04-27 18:38:52 +0800] [42184] [INFO] Running on https://0.0.0.0:6843 (CTRL + C to quit)
[2022-04-27 18:38:52 +0800] [42184] [INFO] Running on http://0.0.0.0:6880 (CTRL + C to quit)
[2022-04-27 18:40:14 +0800] [42184] [INFO] Running on https://0.0.0.0:6843 (CTRL + C to quit)
[2022-04-27 18:40:14 +0800] [42184] [INFO] Running on http://0.0.0.0:6880 (CTRL + C to quit)
[2022-04-27 18:40:58 +0800] [42184] [INFO] Running on https://0.0.0.0:6843 (CTRL + C to quit)
[2022-04-27 18:40:58 +0800] [42184] [INFO] Running on http://0.0.0.0:6880 (CTRL + C to quit)
[2022-04-27 18:41:42 +0800] [42184] [INFO] Running on https://0.0.0.0:6843 (CTRL + C to quit)
[2022-04-27 18:41:42 +0800] [42184] [INFO] Running on http://0.0.0.0:6880 (CTRL + C to quit)
[2022-04-27 18:41:44 +0800] [42184] [INFO] Running on https://0.0.0.0:6843 (CTRL + C to quit)
[2022-04-27 18:41:44 +0800] [42184] [INFO] Running on http://0.0.0.0:6880 (CTRL + C to quit)
[2022-04-27 18:42:50 +0800] [42184] [INFO] Running on https://0.0.0.0:6843 (CTRL + C to quit)
[2022-04-27 18:42:50 +0800] [42184] [INFO] Running on http://0.0.0.0:6880 (CTRL + C to quit)
[2022-04-27 18:43:49 +0800] [42184] [INFO] Running on https://0.0.0.0:6843 (CTRL + C to quit)
[2022-04-27 18:43:49 +0800] [42184] [INFO] Running on http://0.0.0.0:6880 (CTRL + C to quit)
[2022-04-27 18:43:54 +0800] [42464] [INFO] Running on https://0.0.0.0:6843 (CTRL + C to quit)
[2022-04-27 18:43:54 +0800] [42464] [INFO] Running on http://0.0.0.0:6880 (CTRL + C to quit)
[2022-04-27 18:43:57 +0800] [42464] [ERROR] Error in ASGI Framework
Traceback (most recent call last):
  File "/Users/zhangjun/PycharmProjects/OSSGPAPI/venv/lib/python3.8/site-packages/hypercorn/trio/task_group.py", line 21, in _handle
    await invoke_asgi(app, scope, receive, send)
  File "/Users/zhangjun/PycharmProjects/OSSGPAPI/venv/lib/python3.8/site-packages/hypercorn/utils.py", line 247, in invoke_asgi
    await app(scope, receive, send)
  File "/Users/zhangjun/PycharmProjects/OSSGPAPI/venv/lib/python3.8/site-packages/fastapi/applications.py", line 261, in __call__
    await super().__call__(scope, receive, send)
  File "/Users/zhangjun/PycharmProjects/OSSGPAPI/venv/lib/python3.8/site-packages/starlette/applications.py", line 112, in __call__
    await self.middleware_stack(scope, receive, send)
  File "/Users/zhangjun/PycharmProjects/OSSGPAPI/venv/lib/python3.8/site-packages/starlette/middleware/errors.py", line 181, in __call__
    raise exc
  File "/Users/zhangjun/PycharmProjects/OSSGPAPI/venv/lib/python3.8/site-packages/starlette/middleware/errors.py", line 159, in __call__
    await self.app(scope, receive, _send)
  File "/Users/zhangjun/PycharmProjects/OSSGPAPI/venv/lib/python3.8/site-packages/starlette/middleware/cors.py", line 92, in __call__
    await self.simple_response(scope, receive, send, request_headers=headers)
  File "/Users/zhangjun/PycharmProjects/OSSGPAPI/venv/lib/python3.8/site-packages/starlette/middleware/cors.py", line 147, in simple_response
    await self.app(scope, receive, send)
  File "/Users/zhangjun/PycharmProjects/OSSGPAPI/venv/lib/python3.8/site-packages/starlette/exceptions.py", line 82, in __call__
    raise exc
  File "/Users/zhangjun/PycharmProjects/OSSGPAPI/venv/lib/python3.8/site-packages/starlette/exceptions.py", line 71, in __call__
    await self.app(scope, receive, sender)
  File "/Users/zhangjun/PycharmProjects/OSSGPAPI/venv/lib/python3.8/site-packages/fastapi/middleware/asyncexitstack.py", line 21, in __call__
    raise e
  File "/Users/zhangjun/PycharmProjects/OSSGPAPI/venv/lib/python3.8/site-packages/fastapi/middleware/asyncexitstack.py", line 18, in __call__
    await self.app(scope, receive, send)
  File "/Users/zhangjun/PycharmProjects/OSSGPAPI/venv/lib/python3.8/site-packages/starlette/routing.py", line 656, in __call__
    await route.handle(scope, receive, send)
  File "/Users/zhangjun/PycharmProjects/OSSGPAPI/venv/lib/python3.8/site-packages/starlette/routing.py", line 259, in handle
    await self.app(scope, receive, send)
  File "/Users/zhangjun/PycharmProjects/OSSGPAPI/venv/lib/python3.8/site-packages/starlette/routing.py", line 61, in app
    response = await func(request)
  File "/Users/zhangjun/PycharmProjects/OSSGPAPI/venv/lib/python3.8/site-packages/fastapi/routing.py", line 227, in app
    raw_response = await run_endpoint_function(
  File "/Users/zhangjun/PycharmProjects/OSSGPAPI/venv/lib/python3.8/site-packages/fastapi/routing.py", line 160, in run_endpoint_function
    return await dependant.call(**values)
  File "/Users/zhangjun/PycharmProjects/OSSGPAPI/main.py", line 149, in login
    user = security.authenticate_user(apiusers, form_data.username, form_data.password)
  File "/Users/zhangjun/PycharmProjects/OSSGPAPI/core/security.py", line 68, in authenticate_user
    result = fake_db.authenticate(username,password)
  File "/Users/zhangjun/PycharmProjects/OSSGPAPI/venv/lib/python3.8/site-packages/arango_orm/collections.py", line 235, in __getattribute__
    return super(Collection, self).__getattribute__(item)
AttributeError: 'Users' object has no attribute 'authenticate'
[2022-04-27 18:44:32 +0800] [42464] [INFO] Running on https://0.0.0.0:6843 (CTRL + C to quit)
[2022-04-27 18:44:32 +0800] [42464] [INFO] Running on http://0.0.0.0:6880 (CTRL + C to quit)
[2022-04-27 18:44:34 +0800] [42464] [ERROR] Error in ASGI Framework
Traceback (most recent call last):
  File "/Users/zhangjun/PycharmProjects/OSSGPAPI/venv/lib/python3.8/site-packages/hypercorn/trio/task_group.py", line 21, in _handle
    await invoke_asgi(app, scope, receive, send)
  File "/Users/zhangjun/PycharmProjects/OSSGPAPI/venv/lib/python3.8/site-packages/hypercorn/utils.py", line 247, in invoke_asgi
    await app(scope, receive, send)
  File "/Users/zhangjun/PycharmProjects/OSSGPAPI/venv/lib/python3.8/site-packages/fastapi/applications.py", line 261, in __call__
    await super().__call__(scope, receive, send)
  File "/Users/zhangjun/PycharmProjects/OSSGPAPI/venv/lib/python3.8/site-packages/starlette/applications.py", line 112, in __call__
    await self.middleware_stack(scope, receive, send)
  File "/Users/zhangjun/PycharmProjects/OSSGPAPI/venv/lib/python3.8/site-packages/starlette/middleware/errors.py", line 181, in __call__
    raise exc
  File "/Users/zhangjun/PycharmProjects/OSSGPAPI/venv/lib/python3.8/site-packages/starlette/middleware/errors.py", line 159, in __call__
    await self.app(scope, receive, _send)
  File "/Users/zhangjun/PycharmProjects/OSSGPAPI/venv/lib/python3.8/site-packages/starlette/middleware/cors.py", line 92, in __call__
    await self.simple_response(scope, receive, send, request_headers=headers)
  File "/Users/zhangjun/PycharmProjects/OSSGPAPI/venv/lib/python3.8/site-packages/starlette/middleware/cors.py", line 147, in simple_response
    await self.app(scope, receive, send)
  File "/Users/zhangjun/PycharmProjects/OSSGPAPI/venv/lib/python3.8/site-packages/starlette/exceptions.py", line 82, in __call__
    raise exc
  File "/Users/zhangjun/PycharmProjects/OSSGPAPI/venv/lib/python3.8/site-packages/starlette/exceptions.py", line 71, in __call__
    await self.app(scope, receive, sender)
  File "/Users/zhangjun/PycharmProjects/OSSGPAPI/venv/lib/python3.8/site-packages/fastapi/middleware/asyncexitstack.py", line 21, in __call__
    raise e
  File "/Users/zhangjun/PycharmProjects/OSSGPAPI/venv/lib/python3.8/site-packages/fastapi/middleware/asyncexitstack.py", line 18, in __call__
    await self.app(scope, receive, send)
  File "/Users/zhangjun/PycharmProjects/OSSGPAPI/venv/lib/python3.8/site-packages/starlette/routing.py", line 656, in __call__
    await route.handle(scope, receive, send)
  File "/Users/zhangjun/PycharmProjects/OSSGPAPI/venv/lib/python3.8/site-packages/starlette/routing.py", line 259, in handle
    await self.app(scope, receive, send)
  File "/Users/zhangjun/PycharmProjects/OSSGPAPI/venv/lib/python3.8/site-packages/starlette/routing.py", line 61, in app
    response = await func(request)
  File "/Users/zhangjun/PycharmProjects/OSSGPAPI/venv/lib/python3.8/site-packages/fastapi/routing.py", line 227, in app
    raw_response = await run_endpoint_function(
  File "/Users/zhangjun/PycharmProjects/OSSGPAPI/venv/lib/python3.8/site-packages/fastapi/routing.py", line 160, in run_endpoint_function
    return await dependant.call(**values)
  File "/Users/zhangjun/PycharmProjects/OSSGPAPI/main.py", line 149, in login
    user = security.authenticate_user(apiusers, form_data.username, form_data.password)
  File "/Users/zhangjun/PycharmProjects/OSSGPAPI/core/security.py", line 70, in authenticate_user
    user = get_user(fake_db, username)
  File "/Users/zhangjun/PycharmProjects/OSSGPAPI/core/security.py", line 59, in get_user
    ruser = User()
  File "pydantic/main.py", line 331, in pydantic.main.BaseModel.__init__
pydantic.error_wrappers.ValidationError: 1 validation error for User
name
  field required (type=value_error.missing)
[2022-04-27 18:45:53 +0800] [42552] [INFO] Running on https://0.0.0.0:6843 (CTRL + C to quit)
[2022-04-27 18:45:53 +0800] [42552] [INFO] Running on http://0.0.0.0:6880 (CTRL + C to quit)
[2022-04-27 18:45:55 +0800] [42552] [ERROR] Error in ASGI Framework
Traceback (most recent call last):
  File "/Users/zhangjun/PycharmProjects/OSSGPAPI/venv/lib/python3.8/site-packages/hypercorn/trio/task_group.py", line 21, in _handle
    await invoke_asgi(app, scope, receive, send)
  File "/Users/zhangjun/PycharmProjects/OSSGPAPI/venv/lib/python3.8/site-packages/hypercorn/utils.py", line 247, in invoke_asgi
    await app(scope, receive, send)
  File "/Users/zhangjun/PycharmProjects/OSSGPAPI/venv/lib/python3.8/site-packages/fastapi/applications.py", line 261, in __call__
    await super().__call__(scope, receive, send)
  File "/Users/zhangjun/PycharmProjects/OSSGPAPI/venv/lib/python3.8/site-packages/starlette/applications.py", line 112, in __call__
    await self.middleware_stack(scope, receive, send)
  File "/Users/zhangjun/PycharmProjects/OSSGPAPI/venv/lib/python3.8/site-packages/starlette/middleware/errors.py", line 181, in __call__
    raise exc
  File "/Users/zhangjun/PycharmProjects/OSSGPAPI/venv/lib/python3.8/site-packages/starlette/middleware/errors.py", line 159, in __call__
    await self.app(scope, receive, _send)
  File "/Users/zhangjun/PycharmProjects/OSSGPAPI/venv/lib/python3.8/site-packages/starlette/middleware/cors.py", line 92, in __call__
    await self.simple_response(scope, receive, send, request_headers=headers)
  File "/Users/zhangjun/PycharmProjects/OSSGPAPI/venv/lib/python3.8/site-packages/starlette/middleware/cors.py", line 147, in simple_response
    await self.app(scope, receive, send)
  File "/Users/zhangjun/PycharmProjects/OSSGPAPI/venv/lib/python3.8/site-packages/starlette/exceptions.py", line 82, in __call__
    raise exc
  File "/Users/zhangjun/PycharmProjects/OSSGPAPI/venv/lib/python3.8/site-packages/starlette/exceptions.py", line 71, in __call__
    await self.app(scope, receive, sender)
  File "/Users/zhangjun/PycharmProjects/OSSGPAPI/venv/lib/python3.8/site-packages/fastapi/middleware/asyncexitstack.py", line 21, in __call__
    raise e
  File "/Users/zhangjun/PycharmProjects/OSSGPAPI/venv/lib/python3.8/site-packages/fastapi/middleware/asyncexitstack.py", line 18, in __call__
    await self.app(scope, receive, send)
  File "/Users/zhangjun/PycharmProjects/OSSGPAPI/venv/lib/python3.8/site-packages/starlette/routing.py", line 656, in __call__
    await route.handle(scope, receive, send)
  File "/Users/zhangjun/PycharmProjects/OSSGPAPI/venv/lib/python3.8/site-packages/starlette/routing.py", line 259, in handle
    await self.app(scope, receive, send)
  File "/Users/zhangjun/PycharmProjects/OSSGPAPI/venv/lib/python3.8/site-packages/starlette/routing.py", line 61, in app
    response = await func(request)
  File "/Users/zhangjun/PycharmProjects/OSSGPAPI/venv/lib/python3.8/site-packages/fastapi/routing.py", line 227, in app
    raw_response = await run_endpoint_function(
  File "/Users/zhangjun/PycharmProjects/OSSGPAPI/venv/lib/python3.8/site-packages/fastapi/routing.py", line 160, in run_endpoint_function
    return await dependant.call(**values)
  File "/Users/zhangjun/PycharmProjects/OSSGPAPI/main.py", line 149, in login
    user = security.authenticate_user(apiusers, form_data.username, form_data.password)
  File "/Users/zhangjun/PycharmProjects/OSSGPAPI/core/security.py", line 69, in authenticate_user
    if result['userlogin'] == True:
KeyError: 'userlogin'
[2022-04-27 18:47:20 +0800] [42552] [INFO] Running on https://0.0.0.0:6843 (CTRL + C to quit)
[2022-04-27 18:47:20 +0800] [42552] [INFO] Running on http://0.0.0.0:6880 (CTRL + C to quit)
[2022-04-27 18:47:22 +0800] [42552] [ERROR] Error in ASGI Framework
Traceback (most recent call last):
  File "/Users/zhangjun/PycharmProjects/OSSGPAPI/venv/lib/python3.8/site-packages/hypercorn/trio/task_group.py", line 21, in _handle
    await invoke_asgi(app, scope, receive, send)
  File "/Users/zhangjun/PycharmProjects/OSSGPAPI/venv/lib/python3.8/site-packages/hypercorn/utils.py", line 247, in invoke_asgi
    await app(scope, receive, send)
  File "/Users/zhangjun/PycharmProjects/OSSGPAPI/venv/lib/python3.8/site-packages/fastapi/applications.py", line 261, in __call__
    await super().__call__(scope, receive, send)
  File "/Users/zhangjun/PycharmProjects/OSSGPAPI/venv/lib/python3.8/site-packages/starlette/applications.py", line 112, in __call__
    await self.middleware_stack(scope, receive, send)
  File "/Users/zhangjun/PycharmProjects/OSSGPAPI/venv/lib/python3.8/site-packages/starlette/middleware/errors.py", line 181, in __call__
    raise exc
  File "/Users/zhangjun/PycharmProjects/OSSGPAPI/venv/lib/python3.8/site-packages/starlette/middleware/errors.py", line 159, in __call__
    await self.app(scope, receive, _send)
  File "/Users/zhangjun/PycharmProjects/OSSGPAPI/venv/lib/python3.8/site-packages/starlette/middleware/cors.py", line 92, in __call__
    await self.simple_response(scope, receive, send, request_headers=headers)
  File "/Users/zhangjun/PycharmProjects/OSSGPAPI/venv/lib/python3.8/site-packages/starlette/middleware/cors.py", line 147, in simple_response
    await self.app(scope, receive, send)
  File "/Users/zhangjun/PycharmProjects/OSSGPAPI/venv/lib/python3.8/site-packages/starlette/exceptions.py", line 82, in __call__
    raise exc
  File "/Users/zhangjun/PycharmProjects/OSSGPAPI/venv/lib/python3.8/site-packages/starlette/exceptions.py", line 71, in __call__
    await self.app(scope, receive, sender)
  File "/Users/zhangjun/PycharmProjects/OSSGPAPI/venv/lib/python3.8/site-packages/fastapi/middleware/asyncexitstack.py", line 21, in __call__
    raise e
  File "/Users/zhangjun/PycharmProjects/OSSGPAPI/venv/lib/python3.8/site-packages/fastapi/middleware/asyncexitstack.py", line 18, in __call__
    await self.app(scope, receive, send)
  File "/Users/zhangjun/PycharmProjects/OSSGPAPI/venv/lib/python3.8/site-packages/starlette/routing.py", line 656, in __call__
    await route.handle(scope, receive, send)
  File "/Users/zhangjun/PycharmProjects/OSSGPAPI/venv/lib/python3.8/site-packages/starlette/routing.py", line 259, in handle
    await self.app(scope, receive, send)
  File "/Users/zhangjun/PycharmProjects/OSSGPAPI/venv/lib/python3.8/site-packages/starlette/routing.py", line 61, in app
    response = await func(request)
  File "/Users/zhangjun/PycharmProjects/OSSGPAPI/venv/lib/python3.8/site-packages/fastapi/routing.py", line 227, in app
    raw_response = await run_endpoint_function(
  File "/Users/zhangjun/PycharmProjects/OSSGPAPI/venv/lib/python3.8/site-packages/fastapi/routing.py", line 160, in run_endpoint_function
    return await dependant.call(**values)
  File "/Users/zhangjun/PycharmProjects/OSSGPAPI/main.py", line 149, in login
    user = security.authenticate_user(apiusers, form_data.username, form_data.password)
  File "/Users/zhangjun/PycharmProjects/OSSGPAPI/core/security.py", line 69, in authenticate_user
    if result['userlogin'] == True:
KeyError: 'userlogin'
[2022-04-27 18:47:51 +0800] [42552] [INFO] Running on https://0.0.0.0:6843 (CTRL + C to quit)
[2022-04-27 18:47:51 +0800] [42552] [INFO] Running on http://0.0.0.0:6880 (CTRL + C to quit)
[2022-04-27 18:47:55 +0800] [42619] [INFO] Running on https://0.0.0.0:6843 (CTRL + C to quit)
[2022-04-27 18:47:55 +0800] [42619] [INFO] Running on http://0.0.0.0:6880 (CTRL + C to quit)
[2022-04-27 18:47:57 +0800] [42619] [ERROR] Error in ASGI Framework
Traceback (most recent call last):
  File "/Users/zhangjun/PycharmProjects/OSSGPAPI/venv/lib/python3.8/site-packages/hypercorn/trio/task_group.py", line 21, in _handle
    await invoke_asgi(app, scope, receive, send)
  File "/Users/zhangjun/PycharmProjects/OSSGPAPI/venv/lib/python3.8/site-packages/hypercorn/utils.py", line 247, in invoke_asgi
    await app(scope, receive, send)
  File "/Users/zhangjun/PycharmProjects/OSSGPAPI/venv/lib/python3.8/site-packages/fastapi/applications.py", line 261, in __call__
    await super().__call__(scope, receive, send)
  File "/Users/zhangjun/PycharmProjects/OSSGPAPI/venv/lib/python3.8/site-packages/starlette/applications.py", line 112, in __call__
    await self.middleware_stack(scope, receive, send)
  File "/Users/zhangjun/PycharmProjects/OSSGPAPI/venv/lib/python3.8/site-packages/starlette/middleware/errors.py", line 181, in __call__
    raise exc
  File "/Users/zhangjun/PycharmProjects/OSSGPAPI/venv/lib/python3.8/site-packages/starlette/middleware/errors.py", line 159, in __call__
    await self.app(scope, receive, _send)
  File "/Users/zhangjun/PycharmProjects/OSSGPAPI/venv/lib/python3.8/site-packages/starlette/middleware/cors.py", line 92, in __call__
    await self.simple_response(scope, receive, send, request_headers=headers)
  File "/Users/zhangjun/PycharmProjects/OSSGPAPI/venv/lib/python3.8/site-packages/starlette/middleware/cors.py", line 147, in simple_response
    await self.app(scope, receive, send)
  File "/Users/zhangjun/PycharmProjects/OSSGPAPI/venv/lib/python3.8/site-packages/starlette/exceptions.py", line 82, in __call__
    raise exc
  File "/Users/zhangjun/PycharmProjects/OSSGPAPI/venv/lib/python3.8/site-packages/starlette/exceptions.py", line 71, in __call__
    await self.app(scope, receive, sender)
  File "/Users/zhangjun/PycharmProjects/OSSGPAPI/venv/lib/python3.8/site-packages/fastapi/middleware/asyncexitstack.py", line 21, in __call__
    raise e
  File "/Users/zhangjun/PycharmProjects/OSSGPAPI/venv/lib/python3.8/site-packages/fastapi/middleware/asyncexitstack.py", line 18, in __call__
    await self.app(scope, receive, send)
  File "/Users/zhangjun/PycharmProjects/OSSGPAPI/venv/lib/python3.8/site-packages/starlette/routing.py", line 656, in __call__
    await route.handle(scope, receive, send)
  File "/Users/zhangjun/PycharmProjects/OSSGPAPI/venv/lib/python3.8/site-packages/starlette/routing.py", line 259, in handle
    await self.app(scope, receive, send)
  File "/Users/zhangjun/PycharmProjects/OSSGPAPI/venv/lib/python3.8/site-packages/starlette/routing.py", line 61, in app
    response = await func(request)
  File "/Users/zhangjun/PycharmProjects/OSSGPAPI/venv/lib/python3.8/site-packages/fastapi/routing.py", line 227, in app
    raw_response = await run_endpoint_function(
  File "/Users/zhangjun/PycharmProjects/OSSGPAPI/venv/lib/python3.8/site-packages/fastapi/routing.py", line 160, in run_endpoint_function
    return await dependant.call(**values)
  File "/Users/zhangjun/PycharmProjects/OSSGPAPI/main.py", line 149, in login
    user = security.authenticate_user(apiusers, form_data.username, form_data.password)
  File "/Users/zhangjun/PycharmProjects/OSSGPAPI/core/security.py", line 70, in authenticate_user
    user = get_user(fake_db, username)
  File "/Users/zhangjun/PycharmProjects/OSSGPAPI/core/security.py", line 59, in get_user
    ruser = User()
  File "pydantic/main.py", line 331, in pydantic.main.BaseModel.__init__
pydantic.error_wrappers.ValidationError: 1 validation error for User
name
  field required (type=value_error.missing)
[2022-04-27 18:49:10 +0800] [42619] [INFO] Running on https://0.0.0.0:6843 (CTRL + C to quit)
[2022-04-27 18:49:10 +0800] [42619] [INFO] Running on http://0.0.0.0:6880 (CTRL + C to quit)
[2022-04-27 18:49:13 +0800] [42619] [ERROR] Error in ASGI Framework
Traceback (most recent call last):
  File "/Users/zhangjun/PycharmProjects/OSSGPAPI/venv/lib/python3.8/site-packages/hypercorn/trio/task_group.py", line 21, in _handle
    await invoke_asgi(app, scope, receive, send)
  File "/Users/zhangjun/PycharmProjects/OSSGPAPI/venv/lib/python3.8/site-packages/hypercorn/utils.py", line 247, in invoke_asgi
    await app(scope, receive, send)
  File "/Users/zhangjun/PycharmProjects/OSSGPAPI/venv/lib/python3.8/site-packages/fastapi/applications.py", line 261, in __call__
    await super().__call__(scope, receive, send)
  File "/Users/zhangjun/PycharmProjects/OSSGPAPI/venv/lib/python3.8/site-packages/starlette/applications.py", line 112, in __call__
    await self.middleware_stack(scope, receive, send)
  File "/Users/zhangjun/PycharmProjects/OSSGPAPI/venv/lib/python3.8/site-packages/starlette/middleware/errors.py", line 181, in __call__
    raise exc
  File "/Users/zhangjun/PycharmProjects/OSSGPAPI/venv/lib/python3.8/site-packages/starlette/middleware/errors.py", line 159, in __call__
    await self.app(scope, receive, _send)
  File "/Users/zhangjun/PycharmProjects/OSSGPAPI/venv/lib/python3.8/site-packages/starlette/middleware/cors.py", line 92, in __call__
    await self.simple_response(scope, receive, send, request_headers=headers)
  File "/Users/zhangjun/PycharmProjects/OSSGPAPI/venv/lib/python3.8/site-packages/starlette/middleware/cors.py", line 147, in simple_response
    await self.app(scope, receive, send)
  File "/Users/zhangjun/PycharmProjects/OSSGPAPI/venv/lib/python3.8/site-packages/starlette/exceptions.py", line 82, in __call__
    raise exc
  File "/Users/zhangjun/PycharmProjects/OSSGPAPI/venv/lib/python3.8/site-packages/starlette/exceptions.py", line 71, in __call__
    await self.app(scope, receive, sender)
  File "/Users/zhangjun/PycharmProjects/OSSGPAPI/venv/lib/python3.8/site-packages/fastapi/middleware/asyncexitstack.py", line 21, in __call__
    raise e
  File "/Users/zhangjun/PycharmProjects/OSSGPAPI/venv/lib/python3.8/site-packages/fastapi/middleware/asyncexitstack.py", line 18, in __call__
    await self.app(scope, receive, send)
  File "/Users/zhangjun/PycharmProjects/OSSGPAPI/venv/lib/python3.8/site-packages/starlette/routing.py", line 656, in __call__
    await route.handle(scope, receive, send)
  File "/Users/zhangjun/PycharmProjects/OSSGPAPI/venv/lib/python3.8/site-packages/starlette/routing.py", line 259, in handle
    await self.app(scope, receive, send)
  File "/Users/zhangjun/PycharmProjects/OSSGPAPI/venv/lib/python3.8/site-packages/starlette/routing.py", line 61, in app
    response = await func(request)
  File "/Users/zhangjun/PycharmProjects/OSSGPAPI/venv/lib/python3.8/site-packages/fastapi/routing.py", line 227, in app
    raw_response = await run_endpoint_function(
  File "/Users/zhangjun/PycharmProjects/OSSGPAPI/venv/lib/python3.8/site-packages/fastapi/routing.py", line 160, in run_endpoint_function
    return await dependant.call(**values)
  File "/Users/zhangjun/PycharmProjects/OSSGPAPI/main.py", line 158, in login
    access_token_expires = timedelta(minutes=os.getenv("OSSGPAPI_APP_AUTH_TOKEN_EXPIRE_MINUTES"))
TypeError: unsupported type for timedelta minutes component: str
[2022-04-27 18:49:30 +0800] [42619] [INFO] Running on https://0.0.0.0:6843 (CTRL + C to quit)
[2022-04-27 18:49:30 +0800] [42619] [INFO] Running on http://0.0.0.0:6880 (CTRL + C to quit)
[2022-04-27 18:49:37 +0800] [42619] [ERROR] Error in ASGI Framework
Traceback (most recent call last):
  File "/Users/zhangjun/PycharmProjects/OSSGPAPI/venv/lib/python3.8/site-packages/hypercorn/trio/task_group.py", line 21, in _handle
    await invoke_asgi(app, scope, receive, send)
  File "/Users/zhangjun/PycharmProjects/OSSGPAPI/venv/lib/python3.8/site-packages/hypercorn/utils.py", line 247, in invoke_asgi
    await app(scope, receive, send)
  File "/Users/zhangjun/PycharmProjects/OSSGPAPI/venv/lib/python3.8/site-packages/fastapi/applications.py", line 261, in __call__
    await super().__call__(scope, receive, send)
  File "/Users/zhangjun/PycharmProjects/OSSGPAPI/venv/lib/python3.8/site-packages/starlette/applications.py", line 112, in __call__
    await self.middleware_stack(scope, receive, send)
  File "/Users/zhangjun/PycharmProjects/OSSGPAPI/venv/lib/python3.8/site-packages/starlette/middleware/errors.py", line 181, in __call__
    raise exc
  File "/Users/zhangjun/PycharmProjects/OSSGPAPI/venv/lib/python3.8/site-packages/starlette/middleware/errors.py", line 159, in __call__
    await self.app(scope, receive, _send)
  File "/Users/zhangjun/PycharmProjects/OSSGPAPI/venv/lib/python3.8/site-packages/starlette/middleware/cors.py", line 92, in __call__
    await self.simple_response(scope, receive, send, request_headers=headers)
  File "/Users/zhangjun/PycharmProjects/OSSGPAPI/venv/lib/python3.8/site-packages/starlette/middleware/cors.py", line 147, in simple_response
    await self.app(scope, receive, send)
  File "/Users/zhangjun/PycharmProjects/OSSGPAPI/venv/lib/python3.8/site-packages/starlette/exceptions.py", line 82, in __call__
    raise exc
  File "/Users/zhangjun/PycharmProjects/OSSGPAPI/venv/lib/python3.8/site-packages/starlette/exceptions.py", line 71, in __call__
    await self.app(scope, receive, sender)
  File "/Users/zhangjun/PycharmProjects/OSSGPAPI/venv/lib/python3.8/site-packages/fastapi/middleware/asyncexitstack.py", line 21, in __call__
    raise e
  File "/Users/zhangjun/PycharmProjects/OSSGPAPI/venv/lib/python3.8/site-packages/fastapi/middleware/asyncexitstack.py", line 18, in __call__
    await self.app(scope, receive, send)
  File "/Users/zhangjun/PycharmProjects/OSSGPAPI/venv/lib/python3.8/site-packages/starlette/routing.py", line 656, in __call__
    await route.handle(scope, receive, send)
  File "/Users/zhangjun/PycharmProjects/OSSGPAPI/venv/lib/python3.8/site-packages/starlette/routing.py", line 259, in handle
    await self.app(scope, receive, send)
  File "/Users/zhangjun/PycharmProjects/OSSGPAPI/venv/lib/python3.8/site-packages/starlette/routing.py", line 61, in app
    response = await func(request)
  File "/Users/zhangjun/PycharmProjects/OSSGPAPI/venv/lib/python3.8/site-packages/fastapi/routing.py", line 227, in app
    raw_response = await run_endpoint_function(
  File "/Users/zhangjun/PycharmProjects/OSSGPAPI/venv/lib/python3.8/site-packages/fastapi/routing.py", line 160, in run_endpoint_function
    return await dependant.call(**values)
  File "/Users/zhangjun/PycharmProjects/OSSGPAPI/main.py", line 158, in login
    access_token_expires = timedelta(minutes=os.getenv("OSSGPAPI_APP_AUTH_TOKEN_EXPIRE_MINUTES"))
TypeError: unsupported type for timedelta minutes component: str
[2022-04-27 18:49:50 +0800] [42619] [INFO] Running on https://0.0.0.0:6843 (CTRL + C to quit)
[2022-04-27 18:49:50 +0800] [42619] [INFO] Running on http://0.0.0.0:6880 (CTRL + C to quit)
[2022-04-27 18:49:53 +0800] [42619] [ERROR] Error in ASGI Framework
Traceback (most recent call last):
  File "/Users/zhangjun/PycharmProjects/OSSGPAPI/venv/lib/python3.8/site-packages/hypercorn/trio/task_group.py", line 21, in _handle
    await invoke_asgi(app, scope, receive, send)
  File "/Users/zhangjun/PycharmProjects/OSSGPAPI/venv/lib/python3.8/site-packages/hypercorn/utils.py", line 247, in invoke_asgi
    await app(scope, receive, send)
  File "/Users/zhangjun/PycharmProjects/OSSGPAPI/venv/lib/python3.8/site-packages/fastapi/applications.py", line 261, in __call__
    await super().__call__(scope, receive, send)
  File "/Users/zhangjun/PycharmProjects/OSSGPAPI/venv/lib/python3.8/site-packages/starlette/applications.py", line 112, in __call__
    await self.middleware_stack(scope, receive, send)
  File "/Users/zhangjun/PycharmProjects/OSSGPAPI/venv/lib/python3.8/site-packages/starlette/middleware/errors.py", line 181, in __call__
    raise exc
  File "/Users/zhangjun/PycharmProjects/OSSGPAPI/venv/lib/python3.8/site-packages/starlette/middleware/errors.py", line 159, in __call__
    await self.app(scope, receive, _send)
  File "/Users/zhangjun/PycharmProjects/OSSGPAPI/venv/lib/python3.8/site-packages/starlette/middleware/cors.py", line 92, in __call__
    await self.simple_response(scope, receive, send, request_headers=headers)
  File "/Users/zhangjun/PycharmProjects/OSSGPAPI/venv/lib/python3.8/site-packages/starlette/middleware/cors.py", line 147, in simple_response
    await self.app(scope, receive, send)
  File "/Users/zhangjun/PycharmProjects/OSSGPAPI/venv/lib/python3.8/site-packages/starlette/exceptions.py", line 82, in __call__
    raise exc
  File "/Users/zhangjun/PycharmProjects/OSSGPAPI/venv/lib/python3.8/site-packages/starlette/exceptions.py", line 71, in __call__
    await self.app(scope, receive, sender)
  File "/Users/zhangjun/PycharmProjects/OSSGPAPI/venv/lib/python3.8/site-packages/fastapi/middleware/asyncexitstack.py", line 21, in __call__
    raise e
  File "/Users/zhangjun/PycharmProjects/OSSGPAPI/venv/lib/python3.8/site-packages/fastapi/middleware/asyncexitstack.py", line 18, in __call__
    await self.app(scope, receive, send)
  File "/Users/zhangjun/PycharmProjects/OSSGPAPI/venv/lib/python3.8/site-packages/starlette/routing.py", line 656, in __call__
    await route.handle(scope, receive, send)
  File "/Users/zhangjun/PycharmProjects/OSSGPAPI/venv/lib/python3.8/site-packages/starlette/routing.py", line 259, in handle
    await self.app(scope, receive, send)
  File "/Users/zhangjun/PycharmProjects/OSSGPAPI/venv/lib/python3.8/site-packages/starlette/routing.py", line 61, in app
    response = await func(request)
  File "/Users/zhangjun/PycharmProjects/OSSGPAPI/venv/lib/python3.8/site-packages/fastapi/routing.py", line 227, in app
    raw_response = await run_endpoint_function(
  File "/Users/zhangjun/PycharmProjects/OSSGPAPI/venv/lib/python3.8/site-packages/fastapi/routing.py", line 160, in run_endpoint_function
    return await dependant.call(**values)
  File "/Users/zhangjun/PycharmProjects/OSSGPAPI/main.py", line 156, in login
    access_token_expires = timedelta(minutes=os.getenv("OSSGPAPI_APP_AUTH_TOKEN_EXPIRE_MINUTES"))
TypeError: unsupported type for timedelta minutes component: str
[2022-04-27 18:51:22 +0800] [42619] [INFO] Running on https://0.0.0.0:6843 (CTRL + C to quit)
[2022-04-27 18:51:22 +0800] [42619] [INFO] Running on http://0.0.0.0:6880 (CTRL + C to quit)
[2022-04-27 18:51:28 +0800] [42619] [ERROR] Error in ASGI Framework
Traceback (most recent call last):
  File "/Users/zhangjun/PycharmProjects/OSSGPAPI/venv/lib/python3.8/site-packages/hypercorn/trio/task_group.py", line 21, in _handle
    await invoke_asgi(app, scope, receive, send)
  File "/Users/zhangjun/PycharmProjects/OSSGPAPI/venv/lib/python3.8/site-packages/hypercorn/utils.py", line 247, in invoke_asgi
    await app(scope, receive, send)
  File "/Users/zhangjun/PycharmProjects/OSSGPAPI/venv/lib/python3.8/site-packages/fastapi/applications.py", line 261, in __call__
    await super().__call__(scope, receive, send)
  File "/Users/zhangjun/PycharmProjects/OSSGPAPI/venv/lib/python3.8/site-packages/starlette/applications.py", line 112, in __call__
    await self.middleware_stack(scope, receive, send)
  File "/Users/zhangjun/PycharmProjects/OSSGPAPI/venv/lib/python3.8/site-packages/starlette/middleware/errors.py", line 181, in __call__
    raise exc
  File "/Users/zhangjun/PycharmProjects/OSSGPAPI/venv/lib/python3.8/site-packages/starlette/middleware/errors.py", line 159, in __call__
    await self.app(scope, receive, _send)
  File "/Users/zhangjun/PycharmProjects/OSSGPAPI/venv/lib/python3.8/site-packages/starlette/middleware/cors.py", line 92, in __call__
    await self.simple_response(scope, receive, send, request_headers=headers)
  File "/Users/zhangjun/PycharmProjects/OSSGPAPI/venv/lib/python3.8/site-packages/starlette/middleware/cors.py", line 147, in simple_response
    await self.app(scope, receive, send)
  File "/Users/zhangjun/PycharmProjects/OSSGPAPI/venv/lib/python3.8/site-packages/starlette/exceptions.py", line 82, in __call__
    raise exc
  File "/Users/zhangjun/PycharmProjects/OSSGPAPI/venv/lib/python3.8/site-packages/starlette/exceptions.py", line 71, in __call__
    await self.app(scope, receive, sender)
  File "/Users/zhangjun/PycharmProjects/OSSGPAPI/venv/lib/python3.8/site-packages/fastapi/middleware/asyncexitstack.py", line 21, in __call__
    raise e
  File "/Users/zhangjun/PycharmProjects/OSSGPAPI/venv/lib/python3.8/site-packages/fastapi/middleware/asyncexitstack.py", line 18, in __call__
    await self.app(scope, receive, send)
  File "/Users/zhangjun/PycharmProjects/OSSGPAPI/venv/lib/python3.8/site-packages/starlette/routing.py", line 656, in __call__
    await route.handle(scope, receive, send)
  File "/Users/zhangjun/PycharmProjects/OSSGPAPI/venv/lib/python3.8/site-packages/starlette/routing.py", line 259, in handle
    await self.app(scope, receive, send)
  File "/Users/zhangjun/PycharmProjects/OSSGPAPI/venv/lib/python3.8/site-packages/starlette/routing.py", line 61, in app
    response = await func(request)
  File "/Users/zhangjun/PycharmProjects/OSSGPAPI/venv/lib/python3.8/site-packages/fastapi/routing.py", line 227, in app
    raw_response = await run_endpoint_function(
  File "/Users/zhangjun/PycharmProjects/OSSGPAPI/venv/lib/python3.8/site-packages/fastapi/routing.py", line 160, in run_endpoint_function
    return await dependant.call(**values)
  File "/Users/zhangjun/PycharmProjects/OSSGPAPI/main.py", line 158, in login
    data={"sub": user.username}, expires_delta=access_token_expires
AttributeError: 'User' object has no attribute 'username'
[2022-04-27 18:52:08 +0800] [42619] [INFO] Running on https://0.0.0.0:6843 (CTRL + C to quit)
[2022-04-27 18:52:08 +0800] [42619] [INFO] Running on http://0.0.0.0:6880 (CTRL + C to quit)
[2022-04-27 18:54:46 +0800] [42936] [INFO] Running on https://0.0.0.0:6843 (CTRL + C to quit)
[2022-04-27 18:54:46 +0800] [42936] [INFO] Running on http://0.0.0.0:6880 (CTRL + C to quit)
